Workbook

Sheet Interventions
A1: Sr# | B1: Program Level | C1: Activity / Workshops Name | D1: Interventions (Name) | E1: Institution | F1: Program / Course | G1: Batch | H1: Term / Semester | I1: No: of Session Planned | J1: No: of Session Conducted | K1: Micro - Competencies | AC1: Link to Update Score
B2: Level 1 | C2: Art of Storytelling | D2: Storytelling Presentation | E2: JAGSoM | F2: PGDM | G2: 2024 -26 | H2: 2 | I2: 3 | J2: 3 | K2: C1 | L2: C2 | M2: C3 | N2: C5 | O2: E1 | P2: E3 | Q2: A1 | R2: A2 | S2: A3 | T2: A4 | U2: P1 | V2: P2 | W2: P3 | X2: P4 | Y2: T1 | Z2: D3 | AA2: D4 | AB2: D5
B3: Level 1 | C3: Art of Storytelling | D3: Book Review Presentation | E3: JAGSoM | F3: PGDM | G3: 2024 -26 | H3: 2 | I3: 3 | J3: 3 | K3: C1 | L3: C2 | M3: C3 | N3: C5 | O3: E1 | P3: E3 | Q3: A1 | R3: A2 | S3: A3 | T3: A4 | U3: P1 | V3: P2 | W3: P3 | X3: P4 | Y3: T1 | Z3: D3 | AA3: D4 | AB3: D5
B4: Level 1 | C4: Interpersonal Effectivness | E4: JAGSoM | F4: PGDM | G4: 2024 -26 | H4: 2 | I4: 2 | J4: 2
B5: Level 1 | C5: Interpersonal Role Play | E5: JAGSoM | F5: PGDM | G5: 2024 -26 | H5: 2 | I5: 2 | J5: 1 | K5: T4 | L5: T5 | Z5: D3 | AA5: D4 | AB5: D5
B6: Level 1 | C6: Problem Solving | E6: JAGSoM | F6: PGDM | G6: 2024 -26 | H6: 2 | I6: 4 | J6: 4
B7: Level 1 | D7: Case Study Analysis | E7: JAGSoM | F7: PGDM | G7: 2024 -26 | H7: 2 | I7: 0 | J7: 0 | K7: P1 | L7: P2 | M7: P3 | N7: P4 | Z7: D3 | AA7: D4 | AB7: D5
B8: Level 1 | C8: Business Proposal Writing | E8: JAGSoM | F8: PGDM | G8: 2024 -26 | H8: 2 | I8: 1 | J8: 1
B9: Level 1 | D9: Business Proposal Report | E9: JAGSoM | F9: PGDM | G9: 2024 -26 | H9: 2 | I9: 2 | J9: 2 | K9: C1 | L9: A1 | M9: A2 | N9: A3 | O9: A4 | P9: E1 | Q9: P1 | R9: P2 | S9: P3 | T9: P4 | Z9: D3 | AA9: D4 | AB9: D5
B10: Level 1 | C10: Email Writing | E10: JAGSoM | F10: PGDM | G10: 2024 -26 | H10: 2 | I10: 1 | J10: 1
B11: Level 1 | D11: Email Writing | E11: JAGSoM | F11: PGDM | G11: 2024 -26 | H11: 2 | I11: 2 | J11: 2 | K11: C4 | Z11: D3 | AA11: D4 | AB11: D5
B12: Level 1 | C12: Art of Argumentation | E12: JAGSoM | F12: PGDM | G12: 2024 -26 | H12: 2 | I12: 1 | J12: 1
D13: Debating | E13: JAGSoM | F13: PGDM | G13: 2024 -26 | H13: 2 | I13: 3 | J13: 3 | K13: C1 | L13: C2 | M13: C3 | N13: C5 | O13: A1 | P13: A2 | Q13: A3 | R13: A4 | S13: L1 | T13: T1 | Z13: D3 | AA13: D4 | AB13: D5

Sheet Working
A1: Intervention Name : | C1: Story Telling | O1: C1 | P1: C2 | Q1: C3 | R1: C5 | S1: E1 | T1: A1 | U1: A2 | V1: A3 | W1: A4 | X1: P1 | Y1: P2 | Z1: P4 | AA1: T1 | AB1: D4 | AC1: D5
A2: Sr# | B2: Roll Number | C2: Name | D2: Gender | E2: Section | F2: Section | G2: Analytical & Critical Thinking ( A ) | L2: Total | M2: Communication ( C ) | R2: Total | S2: Empathy ( E ) | X2: Total | Y2: Leadership( L ) | AD2: Total | AE2: Negotiation ( N ) | AJ2: Total | AK2: Problem Solving ( P ) | AP2: Total | AQ2: Team Work ( T) | AV2: Total | AW2: Discipline | BB2: Total
G3: A 1 | H3: A 2 | I3: A 3 | J3: A 4 | K3: A 5 | M3: C 1 | N3: C 2 | O3: C 3 | P3: C 4 | Q3: C 5 | S3: E 1 | T3: E 2 | U3: E 3 | V3: E 4 | W3: E 5 | Y3: L 1 | Z3: L 2 | AA3: L 3 | AB3: L 4 | AC3: L 5 | AE3: N 1 | AF3: N 2 | AG3: N 3 | AH3: N 4 | AI3: N 5 | AK3: P 1 | AL3: P 2 | AM3: P 3 | AN3: P 4 | AO3: P 5 | AQ3: T 1 | AR3: T 2 | AS3: T 3 | AT3: T 4 | AU3: T 5 | AW3: D 1 | AX3: D 2 | AY3: D 3 | AZ3: D 4 | BA3: D 5
A4: Column1 | B4: Column2 | C4: Column3 | D4: Column4 | E4: Column5 | F4: Column6 | G4: Column7 | H4: Column8 | I4: Column9 | J4: Column10 | K4: Column11 | L4: Column12 | M4: Column13 | N4: Column14 | O4: Column15 | P4: Column16 | Q4: Column17 | R4: Column18 | S4: Column19 | T4: Column20 | U4: Column21 | V4: Column22 | W4: Column23 | X4: Column24 | Y4: Column25 | Z4: Column26 | AA4: Column27 | AB4: Column28 | AC4: Column29 | AD4: Column30 | AE4: Column31 | AF4: Column32 | AG4: Column33 | AH4: Column34 | AI4: Column35 | AJ4: Column36 | AK4: Column37 | AL4: Column38 | AM4: Column39 | AN4: Column40 | AO4: Column41 | AP4: Column42 | AQ4: Column43 | AR4: Column44 | AS4: Column45 | AT4: Column46 | AU4: Column47 | AV4: Column48 | AW4: Column49 | AX4: Column50 | AY4: Column51 | AZ4: Column52 | BA4: Column53 | BB4: Column54
A5: 1 | B5: 2024JULB00001 | C5: A Divya Sree | D5: Female | E5: A | F5: =REPT(CHAR(160),10)&Working!$E5 -> A | G5: 0 | H5: 0 | I5: 5 | J5: 0 | K5: 0 | L5: 5 | M5: 0 | N5: 4 | O5: 4 | P5: 0 | Q5: 4 | R5: 4 | S5: 0 | T5: 0 | U5: 0 | V5: 0 | W5: 0 | X5: 0 | Y5: 4 | Z5: 0 | AA5: 0 | AB5: 0 | AC5: 0 | AD5: 4 | AE5: 0 | AF5: 0 | AG5: 0 | AH5: 0 | AI5: 4 | AJ5: 0 | AK5: 5 | AL5: 5 | AM5: 0 | AN5: 5 | AO5: 0 | AP5: 5 | AQ5: 5 | AR5: 0 | AS5: 0 | AT5: 0 | AU5: 0 | AV5: 5 | AW5: 0 | AX5: 0 | AY5: 0 | AZ5: 4 | BA5: 5 | BB5: 4.5
A6: 2 | B6: 2024JULB00002 | C6: Aaditya K | D6: Male | E6: A | F6: =REPT(CHAR(160),10)&Working!$E6 -> A | G6: 0 | H6: 0 | I6: 4 | J6: 0 | K6: 0 | L6: 4 | M6: 0 | N6: 4 | O6: 4 | P6: 0 | Q6: 4 | R6: 4 | S6: 0 | T6: 0 | U6: 0 | V6: 0 | W6: 0 | X6: 0 | Y6: 5 | Z6: 0 | AA6: 0 | AB6: 0 | AC6: 0 | AD6: 5 | AE6: 0 | AF6: 0 | AG6: 0 | AH6: 0 | AI6: 0 | AJ6: 0 | AK6: 4 | AL6: 4 | AM6: 0 | AN6: 4 | AO6: 0 | AP6: 4 | AQ6: 4 | AR6: 0 | AS6: 0 | AT6: 0 | AU6: 0 | AV6: 4 | AW6: 0 | AX6: 0 | AY6: 0 | AZ6: 4 | BA6: 4 | BB6: 4
A7: 3 | B7: 2024JULB00003 | C7: Aanchal Sapra | D7: Female | E7: A | F7: =REPT(CHAR(160),10)&Working!$E7 -> A | G7: 0 | H7: 0 | I7: 4 | J7: 0 | K7: 0 | L7: 4 | M7: 0 | N7: 4 | O7: 4 | P7: 0 | Q7: 4 | R7: 4 | S7: 0 | T7: 0 | U7: 0 | V7: 0 | W7: 0 | X7: 0 | Y7: 4 | Z7: 0 | AA7: 0 | AB7: 0 | AC7: 0 | AD7: 4 | AE7: 0 | AF7: 0 | AG7: 0 | AH7: 0 | AI7: 0 | AJ7: 0 | AK7: 4 | AL7: 4 | AM7: 0 | AN7: 4 | AO7: 0 | AP7: 4 | AQ7: 4 | AR7: 0 | AS7: 0 | AT7: 0 | AU7: 0 | AV7: 4 | AW7: 0 | AX7: 0 | AY7: 0 | AZ7: 4 | BA7: 4 | BB7: 4
A8: 4 | B8: 2024JULB00004 | C8: Abhinav B | D8: Male | E8: A | F8: =REPT(CHAR(160),10)&Working!$E8 -> A | G8: 0 | H8: 0 | I8: 4 | J8: 0 | K8: 0 | L8: 4 | M8: 0 | N8: 4 | O8: 5 | P8: 0 | Q8: 5 | R8: 4.6666667 | S8: 0 | T8: 0 | U8: 0 | V8: 0 | W8: 0 | X8: 0 | Y8: 4 | Z8: 0 | AA8: 0 | AB8: 0 | AC8: 0 | AD8: 4 | AE8: 0 | AF8: 0 | AG8: 0 | AH8: 0 | AI8: 0 | AJ8: 0 | AK8: 5 | AL8: 4 | AM8: 0 | AN8: 4 | AO8: 0 | AP8: 4.3333333 | AQ8: 5 | AR8: 0 | AS8: 0 | AT8: 0 | AU8: 0 | AV8: 5 | AW8: 0 | AX8: 0 | AY8: 0 | AZ8: 4 | BA8: 4 | BB8: 4
A9: 5 | B9: 2024JULB00005 | C9: Abhirup Choudhury | D9: Male | E9: D | F9: =REPT(CHAR(160),10)&Working!$E9 -> D | G9: 0 | H9: 0 | I9: A | J9: 0 | K9: 0 | L9: A | M9: 0 | N9: 0 | O9: 0 | P9: 0 | Q9: 0 | R9: 0 | S9: 0 | T9: 0 | U9: 0 | V9: 0 | W9: 0 | X9: 0 | Y9: 0 | Z9: 0 | AA9: 0 | AB9: 0 | AC9: 0 | AD9: 0 | AE9: 0 | AF9: 0 | AG9: 0 | AH9: 0 | AI9: 0 | AJ9: 0 | AK9: 0 | AL9: 0 | AM9: 0 | AN9: 0 | AO9: 0 | AP9: #DIV/0! | AQ9: 0 | AR9: 0 | AS9: 0 | AT9: 0 | AU9: 0 | AV9: 0 | AW9: 0 | AX9: 0 | AY9: 0 | AZ9: 0 | BA9: 0 | BB9: #DIV/0!
A10: 6 | B10: 2024JULB00006 | C10: Abhyuday Tripathi | D10: Male | E10: A | F10: =REPT(CHAR(160),10)&Working!$E10 -> A | G10: 0 | H10: 0 | I10: 4 | J10: 0 | K10: 0 | L10: 4 | M10: 0 | N10: 5 | O10: 4 | P10: 0 | Q10: 4 | R10: 4.3333333 | S10: 0 | T10: 0 | U10: 0 | V10: 0 | W10: 0 | X10: 0 | Y10: 5 | Z10: 0 | AA10: 0 | AB10: 0 | AC10: 0 | AD10: 5 | AE10: 0 | AF10: 0 | AG10: 0 | AH10: 0 | AI10: 0 | AJ10: 0 | AK10: 5 | AL10: 5 | AM10: 0 | AN10: 5 | AO10: 0 | AP10: 5 | AQ10: 5 | AR10: 0 | AS10: 0 | AT10: 0 | AU10: 0 | AV10: 5 | AW10: 0 | AX10: 0 | AY10: 0 | AZ10: 5 | BA10: 5 | BB10: 5
A11: 7 | B11: 2024JULB00007 | C11: Adarsh G | D11: Male | E11: A | F11: =REPT(CHAR(160),10)&Working!$E11 -> A | G11: 0 | H11: 0 | I11: 5 | J11: 0 | K11: 0 | L11: 5 | M11: 0 | N11: 5 | O11: 5 | P11: 0 | Q11: 5 | R11: 5 | S11: 0 | T11: 0 | U11: 0 | V11: 0 | W11: 0 | X11: 0 | Y11: 5 | Z11: 0 | AA11: 0 | AB11: 0 | AC11: 0 | AD11: 5 | AE11: 0 | AF11: 0 | AG11: 0 | AH11: 0 | AI11: 0 | AJ11: 0 | AK11: 4 | AL11: 5 | AM11: 0 | AN11: 5 | AO11: 0 | AP11: 4.6666667 | AQ11: 5 | AR11: 0 | AS11: 0 | AT11: 0 | AU11: 0 | AV11: 5 | AW11: 0 | AX11: 0 | AY11: 0 | AZ11: 5 | BA11: 4 | BB11: 4.5
A12: 8 | B12: 2024JULB00008 | C12: Adarsh Raj Barman | D12: Male | E12: C | F12: =REPT(CHAR(160),10)&Working!$E12 -> C | G12: 0 | H12: 0 | I12: 4 | J12: 0 | K12: 0 | L12: 4 | M12: 0 | N12: 4 | O12: 4 | P12: 0 | Q12: 4 | R12: 4 | S12: 0 | T12: 0 | U12: 0 | V12: 0 | W12: 0 | X12: 0 | Y12: 4 | Z12: 0 | AA12: 0 | AB12: 0 | AC12: 0 | AD12: 4 | AE12: 0 | AF12: 0 | AG12: 0 | AH12: 0 | AI12: 0 | AJ12: 0 | AK12: 4 | AL12: 5 | AM12: 0 | AN12: 5 | AO12: 0 | AP12: 4.6666667 | AQ12: 4 | AR12: 0 | AS12: 0 | AT12: 0 | AU12: 0 | AV12: 4 | AW12: 0 | AX12: 0 | AY12: 0 | AZ12: 4 | BA12: 4 | BB12: 4
A13: 9 | B13: 2024JULB00009 | C13: Aditi Kumari | D13: Female | E13: A | F13: =REPT(CHAR(160),10)&Working!$E13 -> A | G13: 0 | H13: 0 | I13: 4 | J13: 0 | K13: 0 | L13: 4 | M13: 0 | N13: 4 | O13: 4 | P13: 0 | Q13: 4 | R13: 4 | S13: 0 | T13: 0 | U13: 0 | V13: 0 | W13: 0 | X13: 0 | Y13: 4 | Z13: 0 | AA13: 0 | AB13: 0 | AC13: 0 | AD13: 4 | AE13: 0 | AF13: 0 | AG13: 0 | AH13: 0 | AI13: 0 | AJ13: 0 | AK13: 4 | AL13: 5 | AM13: 0 | AN13: 4 | AO13: 0 | AP13: 4.3333333 | AQ13: 5 | AR13: 0 | AS13: 0 | AT13: 0 | AU13: 0 | AV13: 5 | AW13: 0 | AX13: 0 | AY13: 0 | AZ13: 4 | BA13: 4 | BB13: 4
A14: 10 | B14: 2024JULB00012 | C14: Akarsh Narain | D14: Male | E14: A | F14: =REPT(CHAR(160),10)&Working!$E14 -> A | G14: 0 | H14: 0 | I14: 4 | J14: 0 | K14: 0 | L14: 4 | M14: 0 | N14: 4 | O14: 5 | P14: 0 | Q14: 5 | R14: 4.6666667 | S14: 0 | T14: 0 | U14: 0 | V14: 0 | W14: 0 | X14: 0 | Y14: 4 | Z14: 0 | AA14: 0 | AB14: 0 | AC14: 0 | AD14: 4 | AE14: 0 | AF14: 0 | AG14: 0 | AH14: 0 | AI14: 0 | AJ14: 0 | AK14: 5 | AL14: 4 | AM14: 0 | AN14: 5 | AO14: 0 | AP14: 4.6666667 | AQ14: 5 | AR14: 0 | AS14: 0 | AT14: 0 | AU14: 0 | AV14: 5 | AW14: 0 | AX14: 0 | AY14: 0 | AZ14: 4 | BA14: 5 | BB14: 4.5
A15: 11 | B15: 2024JULB00013 | C15: Akshat Singh | D15: Male | E15: B | F15: =REPT(CHAR(160),10)&Working!$E15 -> B | G15: 0 | H15: 0 | I15: 4 | J15: 0 | K15: 0 | L15: 4 | M15: 0 | N15: 4 | O15: 5 | P15: 0 | Q15: 5 | R15: 4.6666667 | S15: 0 | T15: 0 | U15: 0 | V15: 0 | W15: 0 | X15: 0 | Y15: 5 | Z15: 0 | AA15: 0 | AB15: 0 | AC15: 0 | AD15: 5 | AE15: 0 | AF15: 0 | AG15: 0 | AH15: 0 | AI15: 0 | AJ15: 0 | AK15: 4 | AL15: 4 | AM15: 0 | AN15: 4 | AO15: 0 | AP15: 4 | AQ15: 3 | AR15: 0 | AS15: 0 | AT15: 0 | AU15: 0 | AV15: 3 | AW15: 0 | AX15: 0 | AY15: 0 | AZ15: 4 | BA15: 4 | BB15: 4
A16: 12 | B16: 2024JULB00014 | C16: Amal Shibu Balan | D16: Male | E16: B | F16: =REPT(CHAR(160),10)&Working!$E16 -> B | G16: 0 | H16: 0 | I16: 5 | J16: 0 | K16: 0 | L16: 5 | M16: 0 | N16: 4 | O16: 5 | P16: 0 | Q16: 5 | R16: 4.6666667 | S16: 0 | T16: 0 | U16: 0 | V16: 0 | W16: 0 | X16: 0 | Y16: 4 | Z16: 0 | AA16: 0 | AB16: 0 | AC16: 0 | AD16: 4 | AE16: 0 | AF16: 0 | AG16: 0 | AH16: 0 | AI16: 0 | AJ16: 0 | AK16: 4 | AL16: 3 | AM16: 0 | AN16: 4 | AO16: 0 | AP16: 3.6666667 | AQ16: 4 | AR16: 0 | AS16: 0 | AT16: 0 | AU16: 0 | AV16: 4 | AW16: 0 | AX16: 0 | AY16: 0 | AZ16: 4 | BA16: 4 | BB16: 4
A17: 13 | B17: 2024JULB00017 | C17: Anamitra Dutta | D17: Male | E17: A | F17: =REPT(CHAR(160),10)&Working!$E17 -> A | G17: 0 | H17: 0 | I17: 4 | J17: 0 | K17: 0 | L17: 4 | M17: 0 | N17: 4 | O17: 4 | P17: 0 | Q17: 4 | R17: 4 | S17: 0 | T17: 0 | U17: 0 | V17: 0 | W17: 0 | X17: 0 | Y17: 4 | Z17: 0 | AA17: 0 | AB17: 0 | AC17: 0 | AD17: 4 | AE17: 0 | AF17: 0 | AG17: 0 | AH17: 0 | AI17: 0 | AJ17: 0 | AK17: 4 | AL17: 4 | AM17: 0 | AN17: 4 | AO17: 0 | AP17: 4 | AQ17: 4 | AR17: 0 | AS17: 0 | AT17: 0 | AU17: 0 | AV17: 4 | AW17: 0 | AX17: 0 | AY17: 0 | AZ17: 4 | BA17: 4 | BB17: 4
A18: 14 | B18: 2024JULB00019 | C18: Anantaa Paul | D18: Female | E18: B | F18: =REPT(CHAR(160),10)&Working!$E18 -> B | G18: 0 | H18: 0 | I18: 4 | J18: 0 | K18: 0 | L18: 4 | M18: 0 | N18: 4 | O18: 4 | P18: 0 | Q18: 4 | R18: 4 | S18: 0 | T18: 0 | U18: 0 | V18: 0 | W18: 0 | X18: 0 | Y18: 5 | Z18: 0 | AA18: 0 | AB18: 0 | AC18: 0 | AD18: 5 | AE18: 0 | AF18: 0 | AG18: 0 | AH18: 0 | AI18: 0 | AJ18: 0 | AK18: 5 | AL18: 5 | AM18: 0 | AN18: 5 | AO18: 0 | AP18: 5 | AQ18: 0 | AR18: 0 | AS18: 0 | AT18: 0 | AU18: 0 | AV18: 0 | AW18: 0 | AX18: 0 | AY18: 0 | AZ18: 4 | BA18: 4 | BB18: 4
A19: 15 | B19: 2024JULB00020 | C19: Ananya Das | D19: Female | E19: C | F19: =REPT(CHAR(160),10)&Working!$E19 -> C | G19: 0 | H19: 0 | I19: 4 | J19: 0 | K19: 0 | L19: 4 | M19: 0 | N19: 4 | O19: 4 | P19: 0 | Q19: 4 | R19: 4 | S19: 0 | T19: 0 | U19: 0 | V19: 0 | W19: 0 | X19: 0 | Y19: 4 | Z19: 0 | AA19: 0 | AB19: 0 | AC19: 0 | AD19: 4 | AE19: 0 | AF19: 0 | AG19: 0 | AH19: 0 | AI19: 0 | AJ19: 0 | AK19: 4 | AL19: 4 | AM19: 0 | AN19: 4 | AO19: 0 | AP19: 4 | AQ19: 3 | AR19: 0 | AS19: 0 | AT19: 0 | AU19: 0 | AV19: 3 | AW19: 0 | AX19: 0 | AY19: 0 | AZ19: 4 | BA19: 4 | BB19: 4
A20: 16 | B20: 2024JULB00021 | C20: Aniket Inani | D20: Male | E20: A | F20: =REPT(CHAR(160),10)&Working!$E20 -> A | G20: 0 | H20: 0 | I20: 4 | J20: 0 | K20: 0 | L20: 4 | M20: 0 | N20: 4 | O20: 4 | P20: 0 | Q20: 4 | R20: 4 | S20: 0 | T20: 0 | U20: 0 | V20: 0 | W20: 0 | X20: 0 | Y20: 3 | Z20: 0 | AA20: 0 | AB20: 0 | AC20: 0 | AD20: 3 | AE20: 0 | AF20: 0 | AG20: 0 | AH20: 0 | AI20: 0 | AJ20: 0 | AK20: 4 | AL20: 3 | AM20: 0 | AN20: 4 | AO20: 0 | AP20: 3.6666667 | AQ20: 4 | AR20: 0 | AS20: 0 | AT20: 0 | AU20: 0 | AV20: 4 | AW20: 0 | AX20: 0 | AY20: 0 | AZ20: 4 | BA20: 4 | BB20: 4
A21: 17 | B21: 2024JULB00022 | C21: Anupa Maheshwari | D21: Female | E21: C | F21: =REPT(CHAR(160),10)&Working!$E21 -> C | G21: 0 | H21: 0 | I21: 4 | J21: 0 | K21: 0 | L21: 4 | M21: 0 | N21: 4 | O21: 4 | P21: 0 | Q21: 4 | R21: 4 | S21: 0 | T21: 0 | U21: 0 | V21: 0 | W21: 0 | X21: 0 | Y21: 4 | Z21: 0 | AA21: 0 | AB21: 0 | AC21: 0 | AD21: 4 | AE21: 0 | AF21: 0 | AG21: 0 | AH21: 0 | AI21: 0 | AJ21: 0 | AK21: 4 | AL21: 5 | AM21: 0 | AN21: 5 | AO21: 0 | AP21: 4.6666667 | AQ21: 5 | AR21: 0 | AS21: 0 | AT21: 0 | AU21: 0 | AV21: 5 | AW21: 0 | AX21: 0 | AY21: 0 | AZ21: 4 | BA21: 4 | BB21: 4
... A67: 63 | B67: 2024JULB00078 | C67: Keshav Dhoot | D67: Male | E67: A | F67: =REPT(CHAR(160),10)&Working!$E67 -> A | G67: 0 | H67: 0 | I67: 3 | J67: 0 | K67: 0 | L67: 3 | M67: 0 | N67: 3 | O67: 3 | P67: 0 | Q67: 3 | R67: 3 | S67: 0 | T67: 0 | U67: 0 | V67: 0 | W67: 0 | X67: 0 | Y67: 4 | Z67: 0 | AA67: 0 | AB67: 0 | AC67: 0 | AD67: 4 | AE67: 0 | AF67: 0 | AG67: 0 | AH67: 0 | AI67: 0 | AJ67: 0 | AK67: 3 | AL67: 4 | AM67: 0 | AN67: 3 | AO67: 0 | AP67: 3.3333333 | AQ67: 3 | AR67: 0 | AS67: 0 | AT67: 0 | AU67: 0 | AV67: 3 | AW67: 0 | AX67: 0 | AY67: 0 | AZ67: 3 | BA67: 3 | BB67: 3
A68: 64 | B68: 2024JULB00080 | C68: Koustav Biswas | D68: Male | E68: C | F68: =REPT(CHAR(160),10)&Working!$E68 -> C | G68: 0 | H68: 0 | I68: 0 | J68: 0 | K68: 0 | L68: 0 | M68: 0 | N68: 0 | O68: 0 | P68: 0 | Q68: 0 | R68: 0 | S68: 0 | T68: 0 | U68: 0 | V68: 0 | W68: 0 | X68: 0 | Y68: 0 | Z68: 0 | AA68: 0 | AB68: 0 | AC68: 0 | AD68: 0 | AE68: 0 | AF68: 0 | AG68: 0 | AH68: 0 | AI68: 0 | AJ68: 0 | AK68: 0 | AL68: 0 | AM68: 0 | AN68: A | AO68: 0 | AP68: 0 | AQ68: 0 | AR68: 0 | AS68: 0 | AT68: 0 | AU68: 0 | AV68: 0 | AW68: 0 | AX68: 0 | AY68: 0 | AZ68: 0 | BA68: 0 | BB68: 0
A69: 65 | B69: 2024JULB00081 | C69: Krish Chakraborty | D69: Male | E69: A | F69: =REPT(CHAR(160),10)&Working!$E69 -> A | G69: 0 | H69: 0 | I69: 3 | J69: 0 | K69: 0 | L69: 3 | M69: 0 | N69: 3 | O69: 3 | P69: 0 | Q69: 3 | R69: 3 | S69: 0 | T69: 0 | U69: 0 | V69: 0 | W69: 0 | X69: 0 | Y69: 3 | Z69: 0 | AA69: 0 | AB69: 0 | AC69: 0 | AD69: 3 | AE69: 0 | AF69: 0 | AG69: 0 | AH69: 0 | AI69: 0 | AJ69: 0 | AK69: 4 | AL69: 4 | AM69: 0 | AN69: 4 | AO69: 0 | AP69: 4 | AQ69: 4 | AR69: 0 | AS69: 0 | AT69: 0 | AU69: 0 | AV69: 4 | AW69: 0 | AX69: 0 | AY69: 0 | AZ69: 3 | BA69: 3 | BB69: 3
A70: 66 | B70: 2024JULB00083 | C70: Kunal Khurana | D70: Male | E70: B | F70: =REPT(CHAR(160),10)&Working!$E70 -> B | G70: 0 | H70: 0 | I70: 0 | J70: 0 | K70: 0 | L70: 0 | M70: 0 | N70: 0 | O70: 0 | P70: 0 | Q70: 0 | R70: 0 | S70: 0 | T70: 0 | U70: 0 | V70: 0 | W70: 0 | X70: 0 | Y70: 0 | Z70: 0 | AA70: 0 | AB70: 0 | AC70: 0 | AD70: 0 | AE70: 0 | AF70: 0 | AG70: 0 | AH70: 0 | AI70: 0 | AJ70: 0 | AK70: 0 | AL70: 0 | AM70: 0 | AN70: A | AO70: 0 | AP70: 0 | AQ70: 0 | AR70: 0 | AS70: 0 | AT70: 0 | AU70: 0 | AV70: 0 | AW70: 0 | AX70: 0 | AY70: 0 | AZ70: 0 | BA70: 0 | BB70: 0
A71: 67 | B71: 2024JULB00084 | C71: Kushal Badalia | D71: Male | E71: B | F71: =REPT(CHAR(160),10)&Working!$E71 -> B | G71: 0 | H71: 0 | I71: 3 | J71: 0 | K71: 0 | L71: 3 | M71: 0 | N71: 3 | O71: 3 | P71: 0 | Q71: 3 | R71: 3 | S71: 0 | T71: 0 | U71: 0 | V71: 0 | W71: 0 | X71: 0 | Y71: 3 | Z71: 0 | AA71: 0 | AB71: 0 | AC71: 0 | AD71: 3 | AE71: 0 | AF71: 0 | AG71: 0 | AH71: 0 | AI71: 0 | AJ71: 0 | AK71: 4 | AL71: 3 | AM71: 0 | AN71: 3 | AO71: 0 | AP71: 3.3333333 | AQ71: 5 | AR71: 0 | AS71: 0 | AT71: 0 | AU71: 0 | AV71: 5 | AW71: 0 | AX71: 0 | AY71: 0 | AZ71: 3 | BA71: 3 | BB71: 3
A72: 68 | B72: 2024JULB00085 | C72: Kushal Srivastav | D72: Male | E72: B | F72: =REPT(CHAR(160),10)&Working!$E72 -> B | G72: 0 | H72: 0 | I72: 4 | J72: 0 | K72: 0 | L72: 4 | M72: 0 | N72: 4 | O72: 4 | P72: 0 | Q72: 4 | R72: 4 | S72: 0 | T72: 0 | U72: 0 | V72: 0 | W72: 0 | X72: 0 | Y72: 4 | Z72: 0 | AA72: 0 | AB72: 0 | AC72: 0 | AD72: 4 | AE72: 0 | AF72: 0 | AG72: 0 | AH72: 0 | AI72: 0 | AJ72: 0 | AK72: 3 | AL72: 5 | AM72: 0 | AN72: 5 | AO72: 0 | AP72: 4.3333333 | AQ72: 4 | AR72: 0 | AS72: 0 | AT72: 0 | AU72: 0 | AV72: 4 | AW72: 0 | AX72: 0 | AY72: 0 | AZ72: 4 | BA72: 5 | BB72: 4.5
A73: 69 | B73: 2024JULB00086 | C73: Lakshita Chandak | D73: Female | E73: A | F73: =REPT(CHAR(160),10)&Working!$E73 -> A | G73: 0 | H73: 0 | I73: 2 | J73: 0 | K73: 0 | L73: 2 | M73: 0 | N73: 2 | O73: 2 | P73: 0 | Q73: 2 | R73: 2 | S73: 0 | T73: 0 | U73: 0 | V73: 0 | W73: 0 | X73: 0 | Y73: 2 | Z73: 0 | AA73: 0 | AB73: 0 | AC73: 0 | AD73: 2 | AE73: 0 | AF73: 0 | AG73: 0 | AH73: 0 | AI73: 0 | AJ73: 0 | AK73: 2 | AL73: 2 | AM73: 0 | AN73: 2 | AO73: 0 | AP73: 2 | AQ73: 2 | AR73: 0 | AS73: 0 | AT73: 0 | AU73: 0 | AV73: 2 | AW73: 0 | AX73: 0 | AY73: 0 | AZ73: 2 | BA73: 2 | BB73: 2
A74: 70 | B74: 2024JULB00087 | C74: Laxmi Poorvaja S | D74: Female | E74: C | F74: =REPT(CHAR(160),10)&Working!$E74 -> C | G74: 0 | H74: 0 | I74: 2 | J74: 0 | K74: 0 | L74: 2 | M74: 0 | N74: 2 | O74: 2 | P74: 0 | Q74: 2 | R74: 2 | S74: 0 | T74: 0 | U74: 0 | V74: 0 | W74: 0 | X74: 0 | Y74: 2 | Z74: 0 | AA74: 0 | AB74: 0 | AC74: 0 | AD74: 2 | AE74: 0 | AF74: 0 | AG74: 0 | AH74: 0 | AI74: 0 | AJ74: 0 | AK74: 2 | AL74: 3 | AM74: 0 | AN74: 3 | AO74: 0 | AP74: 2.6666667 | AQ74: 3 | AR74: 0 | AS74: 0 | AT74: 0 | AU74: 0 | AV74: 3 | AW74: 0 | AX74: 0 | AY74: 0 | AZ74: 3 | BA74: 2 | BB74: 2.5
A75: 71 | B75: 2024JULB00088 | C75: Leena D | D75: Female | E75: A | F75: =REPT(CHAR(160),10)&Working!$E75 -> A | G75: 0 | H75: 0 | I75: 3 | J75: 0 | K75: 0 | L75: 3 | M75: 0 | N75: 2 | O75: 2 | P75: 0 | Q75: 2 | R75: 2 | S75: 0 | T75: 0 | U75: 0 | V75: 0 | W75: 0 | X75: 0 | Y75: 2 | Z75: 0 | AA75: 0 | AB75: 0 | AC75: 0 | AD75: 2 | AE75: 0 | AF75: 0 | AG75: 0 | AH75: 0 | AI75: 0 | AJ75: 0 | AK75: 3 | AL75: 3 | AM75: 0 | AN75: 3 | AO75: 0 | AP75: 3 | AQ75: 3 | AR75: 0 | AS75: 0 | AT75: 0 | AU75: 0 | AV75: 3 | AW75: 0 | AX75: 0 | AY75: 0 | AZ75: 3 | BA75: 3 | BB75: 3
A76: 72 | B76: 2024JULB00090 | C76: M Maureen Mandy | D76: Female | E76: B | F76: =REPT(CHAR(160),10)&Working!$E76 -> B | G76: 0 | H76: 0 | I76: 2 | J76: 0 | K76: 0 | L76: 2 | M76: 0 | N76: 2 | O76: 2 | P76: 0 | Q76: 2 | R76: 2 | S76: 0 | T76: 0 | U76: 0 | V76: 0 | W76: 0 | X76: 0 | Y76: 2 | Z76: 0 | AA76: 0 | AB76: 0 | AC76: 0 | AD76: 2 | AE76: 0 | AF76: 0 | AG76: 0 | AH76: 0 | AI76: 0 | AJ76: 0 | AK76: 2 | AL76: 2 | AM76: 0 | AN76: 3 | AO76: 0 | AP76: 2.3333333 | AQ76: 2 | AR76: 0 | AS76: 0 | AT76: 0 | AU76: 0 | AV76: 2 | AW76: 0 | AX76: 0 | AY76: 0 | AZ76: 2 | BA76: 3 | BB76: 2.5
A77: 73 | B77: 2024JULB00091 | C77: Madhav Sharma | D77: Male | E77: B | F77: =REPT(CHAR(160),10)&Working!$E77 -> B | G77: 0 | H77: 0 | I77: 3 | J77: 0 | K77: 0 | L77: 3 | M77: 0 | N77: 3 | O77: 3 | P77: 0 | Q77: 3 | R77: 3 | S77: 0 | T77: 0 | U77: 0 | V77: 0 | W77: 0 | X77: 0 | Y77: 3 | Z77: 0 | AA77: 0 | AB77: 0 | AC77: 0 | AD77: 3 | AE77: 0 | AF77: 0 | AG77: 0 | AH77: 0 | AI77: 0 | AJ77: 0 | AK77: 3 | AL77: 4 | AM77: 0 | AN77: 4 | AO77: 0 | AP77: 3.6666667 | AQ77: 4 | AR77: 0 | AS77: 0 | AT77: 0 | AU77: 0 | AV77: 4 | AW77: 0 | AX77: 0 | AY77: 0 | AZ77: 3 | BA77: 3 | BB77: 3
A78: 74 | B78: 2024JULB00093 | C78: Akhileswaradu Manikireddy | D78: Male | E78: C | F78: =REPT(CHAR(160),10)&Working!$E78 -> C | G78: 0 | H78: 0 | I78: 2 | J78: 0 | K78: 0 | L78: 2 | M78: 0 | N78: 2 | O78: 2 | P78: 0 | Q78: 2 | R78: 2 | S78: 0 | T78: 0 | U78: 0 | V78: 0 | W78: 0 | X78: 0 | Y78: 2 | Z78: 0 | AA78: 0 | AB78: 0 | AC78: 0 | AD78: 2 | AE78: 0 | AF78: 0 | AG78: 0 | AH78: 0 | AI78: 0 | AJ78: 0 | AK78: 3 | AL78: 3 | AM78: 0 | AN78: 3 | AO78: 0 | AP78: 3 | AQ78: 4 | AR78: 0 | AS78: 0 | AT78: 0 | AU78: 0 | AV78: 4 | AW78: 0 | AX78: 0 | AY78: 0 | AZ78: 3 | BA78: 3 | BB78: 3
A79: 75 | B79: 2024JULB00094 | C79: Megha Prajapati | D79: Male | E79: C | F79: =REPT(CHAR(160),10)&Working!$E79 -> C | G79: 0 | H79: 0 | I79: 2 | J79: 0 | K79: 0 | L79: 2 | M79: 0 | N79: 2 | O79: 2 | P79: 0 | Q79: 2 | R79: 2 | S79: 0 | T79: 0 | U79: 0 | V79: 0 | W79: 0 | X79: 0 | Y79: 2 | Z79: 0 | AA79: 0 | AB79: 0 | AC79: 0 | AD79: 2 | AE79: 0 | AF79: 0 | AG79: 0 | AH79: 0 | AI79: 0 | AJ79: 0 | AK79: 2 | AL79: 2 | AM79: 0 | AN79: 2 | AO79: 0 | AP79: 2 | AQ79: 2 | AR79: 0 | AS79: 0 | AT79: 0 | AU79: 0 | AV79: 2 | AW79: 0 | AX79: 0 | AY79: 0 | AZ79: 3 | BA79: 2 | BB79: 2.5
A80: 76 | B80: 2024JULB00095 | C80: Melvin Roche. A | D80: Male | E80: C | F80: =REPT(CHAR(160),10)&Working!$E80 -> C | G80: 0 | H80: 0 | I80: 5 | J80: 0 | K80: 0 | L80: 5 | M80: 0 | N80: 5 | O80: 4 | P80: 0 | Q80: 4 | R80: 4.3333333 | S80: 0 | T80: 0 | U80: 0 | V80: 0 | W80: 0 | X80: 0 | Y80: 5 | Z80: 0 | AA80: 0 | AB80: 0 | AC80: 0 | AD80: 5 | AE80: 0 | AF80: 0 | AG80: 0 | AH80: 0 | AI80: 0 | AJ80: 0 | AK80: 5 | AL80: 5 | AM80: 0 | AN80: 5 | AO80: 0 | AP80: 5 | AQ80: 5 | AR80: 0 | AS80: 0 | AT80: 0 | AU80: 0 | AV80: 5 | AW80: 0 | AX80: 0 | AY80: 0 | AZ80: 4 | BA80: 5 | BB80: 4.5
A81: 77 | B81: 2024JULB00096 | C81: Milan Krishna N E | D81: Male | E81: C | F81: =REPT(CHAR(160),10)&Working!$E81 -> C | G81: 0 | H81: 0 | I81: 3 | J81: 0 | K81: 0 | L81: 3 | M81: 0 | N81: 2 | O81: 3 | P81: 0 | Q81: 3 | R81: 2.6666667 | S81: 0 | T81: 0 | U81: 0 | V81: 0 | W81: 0 | X81: 0 | Y81: 3 | Z81: 0 | AA81: 0 | AB81: 0 | AC81: 0 | AD81: 3 | AE81: 0 | AF81: 0 | AG81: 0 | AH81: 0 | AI81: 0 | AJ81: 0 | AK81: 2 | AL81: 3 | AM81: 0 | AN81: 3 | AO81: 0 | AP81: 2.6666667 | AQ81: 3 | AR81: 0 | AS81: 0 | AT81: 0 | AU81: 0 | AV81: 3 | AW81: 0 | AX81: 0 | AY81: 0 | AZ81: 3 | BA81: 3 | BB81: 3
A82: 78 | B82: 2024JULB00098 | C82: Naitik Roy | D82: Male | E82: C | F82: =REPT(CHAR(160),10)&Working!$E82 -> C | G82: 0 | H82: 0 | I82: 2 | J82: 0 | K82: 0 | L82: 2 | M82: 0 | N82: 2 | O82: 2 | P82: 0 | Q82: 2 | R82: 2 | S82: 0 | T82: 0 | U82: 0 | V82: 0 | W82: 0 | X82: 0 | Y82: 2 | Z82: 0 | AA82: 0 | AB82: 0 | AC82: 0 | AD82: 2 | AE82: 0 | AF82: 0 | AG82: 0 | AH82: 0 | AI82: 0 | AJ82: 0 | AK82: 2 | AL82: 3 | AM82: 0 | AN82: 3 | AO82: 0 | AP82: 2.6666667 | AQ82: 3 | AR82: 0 | AS82: 0 | AT82: 0 | AU82: 0 | AV82: 3 | AW82: 0 | AX82: 0 | AY82: 0 | AZ82: 3 | BA82: 2 | BB82: 2.5
... A200: 196 | B200: 2024JULB00239 | C200: Abhishek Nanda | D200: Male | E200: C | F200: =REPT(CHAR(160),10)&Working!$E200 -> C | G200: 0 | H200: 0 | I200: 4 | J200: 0 | K200: 0 | L200: 4 | M200: 0 | N200: 5 | O200: 4 | P200: 0 | Q200: 4 | R200: 4.3333333 | S200: 0 | T200: 0 | U200: 0 | V200: 0 | W200: 0 | X200: 0 | Y200: 4 | Z200: 0 | AA200: 0 | AB200: 0 | AC200: 0 | AD200: 4 | AE200: 0 | AF200: 0 | AG200: 0 | AH200: 0 | AI200: 4 | AJ200: 0 | AK200: 4 | AL200: 4 | AM200: 0 | AN200: 5 | AO200: 0 | AP200: 4.3333333 | AQ200: 3 | AR200: 0 | AS200: 0 | AT200: 0 | AU200: 0 | AV200: 3 | AW200: 0 | AX200: 0 | AY200: 0 | AZ200: 4 | BA200: 5 | BB200: 4.5
A201: 197 | B201: 2024JULB00240 | C201: Prabhansha Vyas | D201: Female | E201: C | F201: =REPT(CHAR(160),10)&Working!$E201 -> C | G201: 0 | H201: 0 | I201: 3 | J201: 0 | K201: 0 | M201: 0 | N201: 2 | O201: 3 | P201: 0 | Q201: 3 | S201: 0 | T201: 0 | U201: 0 | V201: 0 | W201: 0 | X201: 0 | Y201: 4 | Z201: 0 | AA201: 0 | AB201: 0 | AC201: 0 | AE201: 0 | AF201: 0 | AG201: 0 | AH201: 0 | AI201: 0 | AK201: 2 | AL201: 2 | AM201: 0 | AN201: 3 | AO201: 0 | AQ201: 2 | AR201: 0 | AS201: 0 | AT201: 0 | AU201: 0 | AW201: 0 | AX201: 0 | AY201: 0 | AZ201: 3 | BA201: 3
A202: 198 | B202: 2024JULB00241 | C202: Anu Kumari | D202: Female | E202: B | F202: =REPT(CHAR(160),10)&Working!$E202 -> B | G202: 0 | H202: 0 | I202: A | J202: 0 | K202: 0 | L202: 0 | M202: 0 | N202: 0 | O202: 0 | P202: 0 | Q202: 0 | R202: 0 | S202: 0 | T202: 0 | U202: 0 | V202: 0 | W202: 0 | X202: 0 | Y202: 0 | Z202: 0 | AA202: 0 | AB202: 0 | AC202: 0 | AD202: 0 | AE202: 0 | AF202: 0 | AG202: 0 | AH202: 0 | AI202: 0 | AJ202: 0 | AK202: 0 | AL202: 0 | AM202: 0 | AN202: 0 | AO202: 0 | AP202: 0 | AQ202: 0 | AR202: 0 | AS202: 0 | AT202: 0 | AU202: 0 | AV202: 0 | AW202: 0 | AX202: 0 | AY202: 0 | AZ202: 0 | BA202: 0 | BB202: 0
...

Sheet Sheet5
A1: Intervention Name : | C1: Story Telling | E1: C1 | F1: C2 | G1: C3 | H1: C5 | I1: E1 | J1: A1 | K1: A2 | L1: A3 | M1: A4 | N1: P1 | O1: P2 | P1: P4 | Q1: T1 | R1: D4 | S1: D5
A2: Sr# | B2: Roll Number | C2: Name | D2: Gender | E2: Section | F2: Section | G2: Analytical & Critical Thinking ( A ) | L2: Total | M2: Communication ( C ) | R2: Total | S2: Empathy ( E ) | X2: Total | Y2: Leadership( L ) | AD2: Total | AE2: Negotiation ( N ) | AJ2: Total | AK2: Problem Solving ( P ) | AP2: Total | AQ2: Team Work ( T) | AV2: Total | AW2: Discipline | BB2: Total
G3: A 1 | H3: A 2 | I3: A 3 | J3: A 4 | K3: A 5 | M3: C 1 | N3: C 2 | O3: C 3 | P3: C 4 | Q3: C 5 | S3: E 1 | T3: E 2 | U3: E 3 | V3: E 4 | W3: E 5 | Y3: L 1 | Z3: L 2 | AA3: L 3 | AB3: L 4 | AC3: L 5 | AE3: N 1 | AF3: N 2 | AG3: N 3 | AH3: N 4 | AI3: N 5 | AK3: P 1 | AL3: P 2 | AM3: P 3 | AN3: P 4 | AO3: P 5 | AQ3: T 1 | AR3: T 2 | AS3: T 3 | AT3: T 4 | AU3: T 5 | AW3: D 1 | AX3: D 2 | AY3: D 3 | AZ3: D 4 | BA3: D 5
A4: 1 | B4: 2024JULB00001 | C4: A Divya Sree | D4: Female | E4: A | F4: =REPT(CHAR(160),10)&Working!$E5 -> A | G4: =IFERROR(VLOOKUP(Table1215[[#This Row],[Column2]],Table12[[Column2]:[Column54]],6,FALSE),"0") -> 0 | H4: =IFERROR(VLOOKUP(Table1215[[#This Row],[Column2]],Table12[[Column2]:[Column54]],7,FALSE),"0") -> 0 | I4: =IFERROR(VLOOKUP(Table1215[[#This Row],[Column2]],Table12[[Column2]:[Column54]],8,FALSE),"0") -> 5 | J4: =IFERROR(VLOOKUP(Table1215[[#This Row],[Column2]],Table12[[Column2]:[Column54]],9,FALSE),"0") -> 0 | K4: =IFERROR(VLOOKUP(Table1215[[#This Row],[Column2]],Table12[[Column2]:[Column54]],10,FALSE),"0") -> 0 | L4: =Table1215[[#This Row],[Column9]] -> 5 | M4: =IFERROR(VLOOKUP(Table1215[[#This Row],[Column2]],Table12[[Column2]:[Column54]],12,FALSE),"0") -> 0 | N4: =IFERROR(VLOOKUP(Table1215[[#This Row],[Column2]],Table12[[Column2]:[Column54]],13,FALSE),"0") -> 4 | O4: =IFERROR(VLOOKUP(Table1215[[#This Row],[Column2]],Table12[[Column2]:[Column54]],14,FALSE),"0") -> 4 | P4: =IFERROR(VLOOKUP(Table1215[[#This Row],[Column2]],Table12[[Column2]:[Column54]],10,FALSE),"0") -> 0 | Q4: =IFERROR(VLOOKUP(Table1215[[#This Row],[Column2]],Table12[[Column2]:[Column54]],16,FALSE),"0") -> 4 | R4: =AVERAGE(Table1215[[#This Row],[Column14]],Table1215[[#This Row],[Column15]],Table1215[[#This Row],[Column17]]) -> 4 | S4: =IFERROR(VLOOKUP(Table1215[[#This Row],[Column2]],Table12[[Column2]:[Column54]],18,FALSE),"0") -> 0 | T4: =IFERROR(VLOOKUP(Table1215[[#This Row],[Column2]],Table12[[Column2]:[Column54]],19,FALSE),"0") -> 0 | U4: =IFERROR(VLOOKUP(Table1215[[#This Row],[Column2]],Table12[[Column2]:[Column54]],20,FALSE),"0") -> 0 | V4: =IFERROR(VLOOKUP(Table1215[[#This Row],[Column2]],Table12[[Column2]:[Column54]],21,FALSE),"0") -> 0 | W4: =IFERROR(VLOOKUP(Table1215[[#This Row],[Column2]],Table12[[Column2]:[Column54]],22,FALSE),"0") -> 0 | X4: =Table1215[[#This Row],[Column19]] -> 0 | Y4: =IFERROR(VLOOKUP(Table1215[[#This Row],[Column2]],Table12[[Column2]:[Column54]],24,FALSE),"0") -> 4 | Z4: =IFERROR(VLOOKUP(Table1215[[#This Row],[Column2]],Table12[[Column2]:[Column54]],25,FALSE),"0") -> 0 | AA4: =IFERROR(VLOOKUP(Table1215[[#This Row],[Column2]],Table12[[Column2]:[Column54]],26,FALSE),"0") -> 0 | AB4: =IFERROR(VLOOKUP(Table1215[[#This Row],[Column2]],Table12[[Column2]:[Column54]],27,FALSE),"0") -> 0 | AC4: =IFERROR(VLOOKUP(Table1215[[#This Row],[Column2]],Table12[[Column2]:[Column54]],28,FALSE),"0") -> 0 | AD4: =Table1215[[#This Row],[Column25]] -> 4 | AE4: =IFERROR(VLOOKUP(Table1215[[#This Row],[Column2]],Table12[[Column2]:[Column54]],30,FALSE),"0") -> 0 | AF4: =IFERROR(VLOOKUP(Table1215[[#This Row],[Column2]],Table12[[Column2]:[Column54]],31,FALSE),"0") -> 0 | AG4: =IFERROR(VLOOKUP(Table1215[[#This Row],[Column2]],Table12[[Column2]:[Column54]],32,FALSE),"0") -> 0 | AH4: =IFERROR(VLOOKUP(Table1215[[#This Row],[Column2]],Table12[[Column2]:[Column54]],33,FALSE),"0") -> 0 | AI4: =IFERROR(VLOOKUP(Table1215[[#This Row],[Column2]],Table12[[Column2]:[Column54]],34,FALSE),"0") -> 4 | AJ4: =AVERAGE(Table1215[[#This Row],[Column31]],Table1215[[#This Row],[Column32]],Table1215[[#This Row],[Column33]]) -> 0 | AK4: =IFERROR(VLOOKUP(Table1215[[#This Row],[Column2]],Table12[[Column2]:[Column54]],36,FALSE),"0") -> 5 | AL4: =IFERROR(VLOOKUP(Table1215[[#This Row],[Column2]],Table12[[Column2]:[Column54]],37,FALSE),"0") -> 5 | AM4: =IFERROR(VLOOKUP(Table1215[[#This Row],[Column2]],Table12[[Column2]:[Column54]],38,FALSE),"0") -> 0 | AN4: =IFERROR(VLOOKUP(Table1215[[#This Row],[Column2]],Table12[[Column2]:[Column54]],39,FALSE),"0") -> 5 | AO4: =IFERROR(VLOOKUP(Table1215[[#This Row],[Column2]],Table12[[Column2]:[Column54]],40,FALSE),"0") -> 0 | AP4: =AVERAGE(Table1215[[#This Row],[Column37]],Table1215[[#This Row],[Column38]],Table1215[[#This Row],[Column40]]) -> 5 | AQ4: =IFERROR(VLOOKUP(Table1215[[#This Row],[Column2]],Table12[[Column2]:[Column54]],42,FALSE),"0") -> 5 | AR4: =IFERROR(VLOOKUP(Table1215[[#This Row],[Column2]],Table12[[Column2]:[Column54]],43,FALSE),"0") -> 0 | AS4: =IFERROR(VLOOKUP(Table1215[[#This Row],[Column2]],Table12[[Column2]:[Column54]],44,FALSE),"0") -> 0 | AT4: =IFERROR(VLOOKUP(Table1215[[#This Row],[Column2]],Table12[[Column2]:[Column54]],45,FALSE),"0") -> 0 | AU4: =IFERROR(VLOOKUP(Table1215[[#This Row],[Column2]],Table12[[Column2]:[Column54]],46,FALSE),"0") -> 0 | AV4: =Table1215[[#This Row],[Column43]] -> 5 | AW4: =IFERROR(VLOOKUP(Table1215[[#This Row],[Column2]],Table12[[Column2]:[Column54]],48,FALSE),"0") -> 0 | AX4: =IFERROR(VLOOKUP(Table1215[[#This Row],[Column2]],Table12[[Column2]:[Column54]],49,FALSE),"0") -> 0 | AY4: =IFERROR(VLOOKUP(Table1215[[#This Row],[Column2]],Table12[[Column2]:[Column54]],50,FALSE),"0") -> 0 | AZ4: =IFERROR(VLOOKUP(Table1215[[#This Row],[Column2]],Table12[[Column2]:[Column54]],51,FALSE),"0") -> 4 | BA4: =IFERROR(VLOOKUP(Table1215[[#This Row],[Column2]],Table12[[Column2]:[Column54]],52,FALSE),"0") -> 5 | BB4: =AVERAGE(Table1215[[#This Row],[Column52]],Table1215[[#This Row],[Column53]]) -> 4.5
A5: 2 | B5: 2024JULB00002 | C5: Aaditya K | D5: Male | E5: A | F5: =REPT(CHAR(160),10)&Working!$E6 -> A | G5: =IFERROR(VLOOKUP(Table1215[[#This Row],[Column2]],Table12[[Column2]:[Column54]],6,FALSE),"0") -> 0 | H5: =IFERROR(VLOOKUP(Table1215[[#This Row],[Column2]],Table12[[Column2]:[Column54]],7,FALSE),"0") -> 0 | I5: =IFERROR(VLOOKUP(Table1215[[#This Row],[Column2]],Table12[[Column2]:[Column54]],8,FALSE),"0") -> 4 | J5: =IFERROR(VLOOKUP(Table1215[[#This Row],[Column2]],Table12[[Column2]:[Column54]],9,FALSE),"0") -> 0 | K5: =IFERROR(VLOOKUP(Table1215[[#This Row],[Column2]],Table12[[Column2]:[Column54]],10,FALSE),"0") -> 0 | L5: =Table1215[[#This Row],[Column9]] -> 4 | M5: =IFERROR(VLOOKUP(Table1215[[#This Row],[Column2]],Table12[[Column2]:[Column54]],12,FALSE),"0") -> 0 | N5: =IFERROR(VLOOKUP(Table1215[[#This Row],[Column2]],Table12[[Column2]:[Column54]],13,FALSE),"0") -> 4 | O5: =IFERROR(VLOOKUP(Table1215[[#This Row],[Column2]],Table12[[Column2]:[Column54]],14,FALSE),"0") -> 4 | P5: =IFERROR(VLOOKUP(Table1215[[#This Row],[Column2]],Table12[[Column2]:[Column54]],10,FALSE),"0") -> 0 | Q5: =IFERROR(VLOOKUP(Table1215[[#This Row],[Column2]],Table12[[Column2]:[Column54]],16,FALSE),"0") -> 4 | R5: =AVERAGE(Table1215[[#This Row],[Column14]],Table1215[[#This Row],[Column15]],Table1215[[#This Row],[Column17]]) -> 4 | S5: =IFERROR(VLOOKUP(Table1215[[#This Row],[Column2]],Table12[[Column2]:[Column54]],18,FALSE),"0") -> 0 | T5: =IFERROR(VLOOKUP(Table1215[[#This Row],[Column2]],Table12[[Column2]:[Column54]],19,FALSE),"0") -> 0 | U5: =IFERROR(VLOOKUP(Table1215[[#This Row],[Column2]],Table12[[Column2]:[Column54]],20,FALSE),"0") -> 0 | V5: =IFERROR(VLOOKUP(Table1215[[#This Row],[Column2]],Table12[[Column2]:[Column54]],21,FALSE),"0") -> 0 | W5: =IFERROR(VLOOKUP(Table1215[[#This Row],[Column2]],Table12[[Column2]:[Column54]],22,FALSE),"0") -> 0 | X5: =Table1215[[#This Row],[Column19]] -> 0 | Y5: =IFERROR(VLOOKUP(Table1215[[#This Row],[Column2]],Table12[[Column2]:[Column54]],24,FALSE),"0") -> 5 | Z5: =IFERROR(VLOOKUP(Table1215[[#This Row],[Column2]],Table12[[Column2]:[Column54]],25,FALSE),"0") -> 0 | AA5: =IFERROR(VLOOKUP(Table1215[[#This Row],[Column2]],Table12[[Column2]:[Column54]],26,FALSE),"0") -> 0 | AB5: =IFERROR(VLOOKUP(Table1215[[#This Row],[Column2]],Table12[[Column2]:[Column54]],27,FALSE),"0") -> 0 | AC5: =IFERROR(VLOOKUP(Table1215[[#This Row],[Column2]],Table12[[Column2]:[Column54]],28,FALSE),"0") -> 0 | AD5: =Table1215[[#This Row],[Column25]] -> 5 | AE5: =IFERROR(VLOOKUP(Table1215[[#This Row],[Column2]],Table12[[Column2]:[Column54]],30,FALSE),"0") -> 0 | AF5: =IFERROR(VLOOKUP(Table1215[[#This Row],[Column2]],Table12[[Column2]:[Column54]],31,FALSE),"0") -> 0 | AG5: =IFERROR(VLOOKUP(Table1215[[#This Row],[Column2]],Table12[[Column2]:[Column54]],32,FALSE),"0") -> 0 | AH5: =IFERROR(VLOOKUP(Table1215[[#This Row],[Column2]],Table12[[Column2]:[Column54]],33,FALSE),"0") -> 0 | AI5: =IFERROR(VLOOKUP(Table1215[[#This Row],[Column2]],Table12[[Column2]:[Column54]],34,FALSE),"0") -> 0 | AJ5: =AVERAGE(Table1215[[#This Row],[Column31]],Table1215[[#This Row],[Column32]],Table1215[[#This Row],[Column33]]) -> 0 | AK5: =IFERROR(VLOOKUP(Table1215[[#This Row],[Column2]],Table12[[Column2]:[Column54]],36,FALSE),"0") -> 4 | AL5: =IFERROR(VLOOKUP(Table1215[[#This Row],[Column2]],Table12[[Column2]:[Column54]],37,FALSE),"0") -> 4 | AM5: =IFERROR(VLOOKUP(Table1215[[#This Row],[Column2]],Table12[[Column2]:[Column54]],38,FALSE),"0") -> 0 | AN5: =IFERROR(VLOOKUP(Table1215[[#This Row],[Column2]],Table12[[Column2]:[Column54]],39,FALSE),"0") -> 4 | AO5: =IFERROR(VLOOKUP(Table1215[[#This Row],[Column2]],Table12[[Column2]:[Column54]],40,FALSE),"0") -> 0 | AP5: =AVERAGE(Table1215[[#This Row],[Column37]],Table1215[[#This Row],[Column38]],Table1215[[#This Row],[Column40]]) -> 4 | AQ5: =IFERROR(VLOOKUP(Table1215[[#This Row],[Column2]],Table12[[Column2]:[Column54]],42,FALSE),"0") -> 4 | AR5: =IFERROR(VLOOKUP(Table1215[[#This Row],[Column2]],Table12[[Column2]:[Column54]],43,FALSE),"0") -> 0 | AS5: =IFERROR(VLOOKUP(Table1215[[#This Row],[Column2]],Table12[[Column2]:[Column54]],44,FALSE),"0") -> 0 | AT5: =IFERROR(VLOOKUP(Table1215[[#This Row],[Column2]],Table12[[Column2]:[Column54]],45,FALSE),"0") -> 0 | AU5: =IFERROR(VLOOKUP(Table1215[[#This Row],[Column2]],Table12[[Column2]:[Column54]],46,FALSE),"0") -> 0 | AV5: =Table1215[[#This Row],[Column43]] -> 4 | AW5: =IFERROR(VLOOKUP(Table1215[[#This Row],[Column2]],Table12[[Column2]:[Column54]],48,FALSE),"0") -> 0 | AX5: =IFERROR(VLOOKUP(Table1215[[#This Row],[Column2]],Table12[[Column2]:[Column54]],49,FALSE),"0") -> 0 | AY5: =IFERROR(VLOOKUP(Table1215[[#This Row],[Column2]],Table12[[Column2]:[Column54]],50,FALSE),"0") -> 0 | AZ5: =IFERROR(VLOOKUP(Table1215[[#This Row],[Column2]],Table12[[Column2]:[Column54]],51,FALSE),"0") -> 4 | BA5: =IFERROR(VLOOKUP(Table1215[[#This Row],[Column2]],Table12[[Column2]:[Column54]],52,FALSE),"0") -> 4 | BB5: =AVERAGE(Table1215[[#This Row],[Column52]],Table1215[[#This Row],[Column53]]) -> 4
A6: 3 | B6: 2024JULB00003 | C6: Aanchal Sapra | D6: Female | E6: A | F6: =REPT(CHAR(160),10)&Working!$E7 -> A | G6: =IFERROR(VLOOKUP(Table1215[[#This Row],[Column2]],Table12[[Column2]:[Column54]],6,FALSE),"0") -> 0 | H6: =IFERROR(VLOOKUP(Table1215[[#This Row],[Column2]],Table12[[Column2]:[Column54]],7,FALSE),"0") -> 0 | I6: =IFERROR(VLOOKUP(Table1215[[#This Row],[Column2]],Table12[[Column2]:[Column54]],8,FALSE),"0") -> 4 | J6: =IFERROR(VLOOKUP(Table1215[[#This Row],[Column2]],Table12[[Column2]:[Column54]],9,FALSE),"0") -> 0 | K6: =IFERROR(VLOOKUP(Table1215[[#This Row],[Column2]],Table12[[Column2]:[Column54]],10,FALSE),"0") -> 0 | L6: =Table1215[[#This Row],[Column9]] -> 4 | M6: =IFERROR(VLOOKUP(Table1215[[#This Row],[Column2]],Table12[[Column2]:[Column54]],12,FALSE),"0") -> 0 | N6: =IFERROR(VLOOKUP(Table1215[[#This Row],[Column2]],Table12[[Column2]:[Column54]],13,FALSE),"0") -> 4 | O6: =IFERROR(VLOOKUP(Table1215[[#This Row],[Column2]],Table12[[Column2]:[Column54]],14,FALSE),"0") -> 4 | P6: =IFERROR(VLOOKUP(Table1215[[#This Row],[Column2]],Table12[[Column2]:[Column54]],10,FALSE),"0") -> 0 | Q6: =IFERROR(VLOOKUP(Table1215[[#This Row],[Column2]],Table12[[Column2]:[Column54]],16,FALSE),"0") -> 4 | R6: =AVERAGE(Table1215[[#This Row],[Column14]],Table1215[[#This Row],[Column15]],Table1215[[#This Row],[Column17]]) -> 4 | S6: =IFERROR(VLOOKUP(Table1215[[#This Row],[Column2]],Table12[[Column2]:[Column54]],18,FALSE),"0") -> 0 | T6: =IFERROR(VLOOKUP(Table1215[[#This Row],[Column2]],Table12[[Column2]:[Column54]],19,FALSE),"0") -> 0 | U6: =IFERROR(VLOOKUP(Table1215[[#This Row],[Column2]],Table12[[Column2]:[Column54]],20,FALSE),"0") -> 0 | V6: =IFERROR(VLOOKUP(Table1215[[#This Row],[Column2]],Table12[[Column2]:[Column54]],21,FALSE),"0") -> 0 | W6: =IFERROR(VLOOKUP(Table1215[[#This Row],[Column2]],Table12[[Column2]:[Column54]],22,FALSE),"0") -> 0 | X6: =Table1215[[#This Row],[Column19]] -> 0 | Y6: =IFERROR(VLOOKUP(Table1215[[#This Row],[Column2]],Table12[[Column2]:[Column54]],24,FALSE),"0") -> 4 | Z6: =IFERROR(VLOOKUP(Table1215[[#This Row],[Column2]],Table12[[Column2]:[Column54]],25,FALSE),"0") -> 0 | AA6: =IFERROR(VLOOKUP(Table1215[[#This Row],[Column2]],Table12[[Column2]:[Column54]],26,FALSE),"0") -> 0 | AB6: =IFERROR(VLOOKUP(Table1215[[#This Row],[Column2]],Table12[[Column2]:[Column54]],27,FALSE),"0") -> 0 | AC6: =IFERROR(VLOOKUP(Table1215[[#This Row],[Column2]],Table12[[Column2]:[Column54]],28,FALSE),"0") -> 0 | AD6: =Table1215[[#This Row],[Column25]] -> 4 | AE6: =IFERROR(VLOOKUP(Table1215[[#This Row],[Column2]],Table12[[Column2]:[Column54]],30,FALSE),"0") -> 0 | AF6: =IFERROR(VLOOKUP(Table1215[[#This Row],[Column2]],Table12[[Column2]:[Column54]],31,FALSE),"0") -> 0 | AG6: =IFERROR(VLOOKUP(Table1215[[#This Row],[Column2]],Table12[[Column2]:[Column54]],32,FALSE),"0") -> 0 | AH6: =IFERROR(VLOOKUP(Table1215[[#This Row],[Column2]],Table12[[Column2]:[Column54]],33,FALSE),"0") -> 0 | AI6: =IFERROR(VLOOKUP(Table1215[[#This Row],[Column2]],Table12[[Column2]:[Column54]],34,FALSE),"0") -> 0 | AJ6: =AVERAGE(Table1215[[#This Row],[Column31]],Table1215[[#This Row],[Column32]],Table1215[[#This Row],[Column33]]) -> 0 | AK6: =IFERROR(VLOOKUP(Table1215[[#This Row],[Column2]],Table12[[Column2]:[Column54]],36,FALSE),"0") -> 4 | AL6: =IFERROR(VLOOKUP(Table1215[[#This Row],[Column2]],Table12[[Column2]:[Column54]],37,FALSE),"0") -> 4 | AM6: =IFERROR(VLOOKUP(Table1215[[#This Row],[Column2]],Table12[[Column2]:[Column54]],38,FALSE),"0") -> 0 | AN6: =IFERROR(VLOOKUP(Table1215[[#This Row],[Column2]],Table12[[Column2]:[Column54]],39,FALSE),"0") -> 4 | AO6: =IFERROR(VLOOKUP(Table1215[[#This Row],[Column2]],Table12[[Column2]:[Column54]],40,FALSE),"0") -> 0 | AP6: =AVERAGE(Table1215[[#This Row],[Column37]],Table1215[[#This Row],[Column38]],Table1215[[#This Row],[Column40]]) -> 4 | AQ6: =IFERROR(VLOOKUP(Table1215[[#This Row],[Column2]],Table12[[Column2]:[Column54]],42,FALSE),"0") -> 4 | AR6: =IFERROR(VLOOKUP(Table1215[[#This Row],[Column2]],Table12[[Column2]:[Column54]],43,FALSE),"0") -> 0 | AS6: =IFERROR(VLOOKUP(Table1215[[#This Row],[Column2]],Table12[[Column2]:[Column54]],44,FALSE),"0") -> 0 | AT6: =IFERROR(VLOOKUP(Table1215[[#This Row],[Column2]],Table12[[Column2]:[Column54]],45,FALSE),"0") -> 0 | AU6: =IFERROR(VLOOKUP(Table1215[[#This Row],[Column2]],Table12[[Column2]:[Column54]],46,FALSE),"0") -> 0 | AV6: =Table1215[[#This Row],[Column43]] -> 4 | AW6: =IFERROR(VLOOKUP(Table1215[[#This Row],[Column2]],Table12[[Column2]:[Column54]],48,FALSE),"0") -> 0 | AX6: =IFERROR(VLOOKUP(Table1215[[#This Row],[Column2]],Table12[[Column2]:[Column54]],49,FALSE),"0") -> 0 | AY6: =IFERROR(VLOOKUP(Table1215[[#This Row],[Column2]],Table12[[Column2]:[Column54]],50,FALSE),"0") -> 0 | AZ6: =IFERROR(VLOOKUP(Table1215[[#This Row],[Column2]],Table12[[Column2]:[Column54]],51,FALSE),"0") -> 4 | BA6: =IFERROR(VLOOKUP(Table1215[[#This Row],[Column2]],Table12[[Column2]:[Column54]],52,FALSE),"0") -> 4 | BB6: =AVERAGE(Table1215[[#This Row],[Column52]],Table1215[[#This Row],[Column53]]) -> 4
A7: 4 | B7: 2024JULB00004 | C7: Abhinav B | D7: Male | E7: A | F7: =REPT(CHAR(160),10)&Working!$E8 -> A | G7: =IFERROR(VLOOKUP(Table1215[[#This Row],[Column2]],Table12[[Column2]:[Column54]],6,FALSE),"0") -> 0 | H7: =IFERROR(VLOOKUP(Table1215[[#This Row],[Column2]],Table12[[Column2]:[Column54]],7,FALSE),"0") -> 0 | I7: =IFERROR(VLOOKUP(Table1215[[#This Row],[Column2]],Table12[[Column2]:[Column54]],8,FALSE),"0") -> 4 | J7: =IFERROR(VLOOKUP(Table1215[[#This Row],[Column2]],Table12[[Column2]:[Column54]],9,FALSE),"0") -> 0 | K7: =IFERROR(VLOOKUP(Table1215[[#This Row],[Column2]],Table12[[Column2]:[Column54]],10,FALSE),"0") -> 0 | L7: =Table1215[[#This Row],[Column9]] -> 4 | M7: =IFERROR(VLOOKUP(Table1215[[#This Row],[Column2]],Table12[[Column2]:[Column54]],12,FALSE),"0") -> 0 | N7: =IFERROR(VLOOKUP(Table1215[[#This Row],[Column2]],Table12[[Column2]:[Column54]],13,FALSE),"0") -> 4 | O7: =IFERROR(VLOOKUP(Table1215[[#This Row],[Column2]],Table12[[Column2]:[Column54]],14,FALSE),"0") -> 5 | P7: =IFERROR(VLOOKUP(Table1215[[#This Row],[Column2]],Table12[[Column2]:[Column54]],10,FALSE),"0") -> 0 | Q7: =IFERROR(VLOOKUP(Table1215[[#This Row],[Column2]],Table12[[Column2]:[Column54]],16,FALSE),"0") -> 5 | R7: =AVERAGE(Table1215[[#This Row],[Column14]],Table1215[[#This Row],[Column15]],Table1215[[#This Row],[Column17]]) -> 4.6666667 | S7: =IFERROR(VLOOKUP(Table1215[[#This Row],[Column2]],Table12[[Column2]:[Column54]],18,FALSE),"0") -> 0 | T7: =IFERROR(VLOOKUP(Table1215[[#This Row],[Column2]],Table12[[Column2]:[Column54]],19,FALSE),"0") -> 0 | U7: =IFERROR(VLOOKUP(Table1215[[#This Row],[Column2]],Table12[[Column2]:[Column54]],20,FALSE),"0") -> 0 | V7: =IFERROR(VLOOKUP(Table1215[[#This Row],[Column2]],Table12[[Column2]:[Column54]],21,FALSE),"0") -> 0 | W7: =IFERROR(VLOOKUP(Table1215[[#This Row],[Column2]],Table12[[Column2]:[Column54]],22,FALSE),"0") -> 0 | X7: =Table1215[[#This Row],[Column19]] -> 0 | Y7: =IFERROR(VLOOKUP(Table1215[[#This Row],[Column2]],Table12[[Column2]:[Column54]],24,FALSE),"0") -> 4 | Z7: =IFERROR(VLOOKUP(Table1215[[#This Row],[Column2]],Table12[[Column2]:[Column54]],25,FALSE),"0") -> 0 | AA7: =IFERROR(VLOOKUP(Table1215[[#This Row],[Column2]],Table12[[Column2]:[Column54]],26,FALSE),"0") -> 0 | AB7: =IFERROR(VLOOKUP(Table1215[[#This Row],[Column2]],Table12[[Column2]:[Column54]],27,FALSE),"0") -> 0 | AC7: =IFERROR(VLOOKUP(Table1215[[#This Row],[Column2]],Table12[[Column2]:[Column54]],28,FALSE),"0") -> 0 | AD7: =Table1215[[#This Row],[Column25]] -> 4 | AE7: =IFERROR(VLOOKUP(Table1215[[#This Row],[Column2]],Table12[[Column2]:[Column54]],30,FALSE),"0") -> 0 | AF7: =IFERROR(VLOOKUP(Table1215[[#This Row],[Column2]],Table12[[Column2]:[Column54]],31,FALSE),"0") -> 0 | AG7: =IFERROR(VLOOKUP(Table1215[[#This Row],[Column2]],Table12[[Column2]:[Column54]],32,FALSE),"0") -> 0 | AH7: =IFERROR(VLOOKUP(Table1215[[#This Row],[Column2]],Table12[[Column2]:[Column54]],33,FALSE),"0") -> 0 | AI7: =IFERROR(VLOOKUP(Table1215[[#This Row],[Column2]],Table12[[Column2]:[Column54]],34,FALSE),"0") -> 0 | AJ7: =AVERAGE(Table1215[[#This Row],[Column31]],Table1215[[#This Row],[Column32]],Table1215[[#This Row],[Column33]]) -> 0 | AK7: =IFERROR(VLOOKUP(Table1215[[#This Row],[Column2]],Table12[[Column2]:[Column54]],36,FALSE),"0") -> 5 | AL7: =IFERROR(VLOOKUP(Table1215[[#This Row],[Column2]],Table12[[Column2]:[Column54]],37,FALSE),"0") -> 4 | AM7: =IFERROR(VLOOKUP(Table1215[[#This Row],[Column2]],Table12[[Column2]:[Column54]],38,FALSE),"0") -> 0 | AN7: =IFERROR(VLOOKUP(Table1215[[#This Row],[Column2]],Table12[[Column2]:[Column54]],39,FALSE),"0") -> 4 | AO7: =IFERROR(VLOOKUP(Table1215[[#This Row],[Column2]],Table12[[Column2]:[Column54]],40,FALSE),"0") -> 0 | AP7: =AVERAGE(Table1215[[#This Row],[Column37]],Table1215[[#This Row],[Column38]],Table1215[[#This Row],[Column40]]) -> 4.3333333 | AQ7: =IFERROR(VLOOKUP(Table1215[[#This Row],[Column2]],Table12[[Column2]:[Column54]],42,FALSE),"0") -> 5 | AR7: =IFERROR(VLOOKUP(Table1215[[#This Row],[Column2]],Table12[[Column2]:[Column54]],43,FALSE),"0") -> 0 | AS7: =IFERROR(VLOOKUP(Table1215[[#This Row],[Column2]],Table12[[Column2]:[Column54]],44,FALSE),"0") -> 0 | AT7: =IFERROR(VLOOKUP(Table1215[[#This Row],[Column2]],Table12[[Column2]:[Column54]],45,FALSE),"0") -> 0 | AU7: =IFERROR(VLOOKUP(Table1215[[#This Row],[Column2]],Table12[[Column2]:[Column54]],46,FALSE),"0") -> 0 | AV7: =Table1215[[#This Row],[Column43]] -> 5 | AW7: =IFERROR(VLOOKUP(Table1215[[#This Row],[Column2]],Table12[[Column2]:[Column54]],48,FALSE),"0") -> 0 | AX7: =IFERROR(VLOOKUP(Table1215[[#This Row],[Column2]],Table12[[Column2]:[Column54]],49,FALSE),"0") -> 0 | AY7: =IFERROR(VLOOKUP(Table1215[[#This Row],[Column2]],Table12[[Column2]:[Column54]],50,FALSE),"0") -> 0 | AZ7: =IFERROR(VLOOKUP(Table1215[[#This Row],[Column2]],Table12[[Column2]:[Column54]],51,FALSE),"0") -> 4 | BA7: =IFERROR(VLOOKUP(Table1215[[#This Row],[Column2]],Table12[[Column2]:[Column54]],52,FALSE),"0") -> 4 | BB7: =AVERAGE(Table1215[[#This Row],[Column52]],Table1215[[#This Row],[Column53]]) -> 4
A8: 5 | B8: 2024JULB00005 | C8: Abhirup Choudhury | D8: Male | E8: D | F8: =REPT(CHAR(160),10)&Working!$E9 -> D | G8: =IFERROR(VLOOKUP(Table1215[[#This Row],[Column2]],Table12[[Column2]:[Column54]],6,FALSE),"0") -> 0 | H8: =IFERROR(VLOOKUP(Table1215[[#This Row],[Column2]],Table12[[Column2]:[Column54]],7,FALSE),"0") -> 0 | I8: =IFERROR(VLOOKUP(Table1215[[#This Row],[Column2]],Table12[[Column2]:[Column54]],8,FALSE),"0") -> A | J8: =IFERROR(VLOOKUP(Table1215[[#This Row],[Column2]],Table12[[Column2]:[Column54]],9,FALSE),"0") -> 0 | K8: =IFERROR(VLOOKUP(Table1215[[#This Row],[Column2]],Table12[[Column2]:[Column54]],10,FALSE),"0") -> 0 | L8: =Table1215[[#This Row],[Column9]] -> A | M8: =IFERROR(VLOOKUP(Table1215[[#This Row],[Column2]],Table12[[Column2]:[Column54]],12,FALSE),"0") -> 0 | N8: =IFERROR(VLOOKUP(Table1215[[#This Row],[Column2]],Table12[[Column2]:[Column54]],13,FALSE),"0") -> 0 | O8: =IFERROR(VLOOKUP(Table1215[[#This Row],[Column2]],Table12[[Column2]:[Column54]],14,FALSE),"0") -> 0 | P8: =IFERROR(VLOOKUP(Table1215[[#This Row],[Column2]],Table12[[Column2]:[Column54]],10,FALSE),"0") -> 0 | Q8: =IFERROR(VLOOKUP(Table1215[[#This Row],[Column2]],Table12[[Column2]:[Column54]],16,FALSE),"0") -> 0 | R8: =AVERAGE(Table1215[[#This Row],[Column14]],Table1215[[#This Row],[Column15]],Table1215[[#This Row],[Column17]]) -> #DIV/0! | S8: =IFERROR(VLOOKUP(Table1215[[#This Row],[Column2]],Table12[[Column2]:[Column54]],18,FALSE),"0") -> 0 | T8: =IFERROR(VLOOKUP(Table1215[[#This Row],[Column2]],Table12[[Column2]:[Column54]],19,FALSE),"0") -> 0 | U8: =IFERROR(VLOOKUP(Table1215[[#This Row],[Column2]],Table12[[Column2]:[Column54]],20,FALSE),"0") -> 0 | V8: =IFERROR(VLOOKUP(Table1215[[#This Row],[Column2]],Table12[[Column2]:[Column54]],21,FALSE),"0") -> 0 | W8: =IFERROR(VLOOKUP(Table1215[[#This Row],[Column2]],Table12[[Column2]:[Column54]],22,FALSE),"0") -> 0 | X8: =Table1215[[#This Row],[Column19]] -> 0 | Y8: =IFERROR(VLOOKUP(Table1215[[#This Row],[Column2]],Table12[[Column2]:[Column54]],24,FALSE),"0") -> 0 | Z8: =IFERROR(VLOOKUP(Table1215[[#This Row],[Column2]],Table12[[Column2]:[Column54]],25,FALSE),"0") -> 0 | AA8: =IFERROR(VLOOKUP(Table1215[[#This Row],[Column2]],Table12[[Column2]:[Column54]],26,FALSE),"0") -> 0 | AB8: =IFERROR(VLOOKUP(Table1215[[#This Row],[Column2]],Table12[[Column2]:[Column54]],27,FALSE),"0") -> 0 | AC8: =IFERROR(VLOOKUP(Table1215[[#This Row],[Column2]],Table12[[Column2]:[Column54]],28,FALSE),"0") -> 0 | AD8: =Table1215[[#This Row],[Column25]] -> 0 | AE8: =IFERROR(VLOOKUP(Table1215[[#This Row],[Column2]],Table12[[Column2]:[Column54]],30,FALSE),"0") -> 0 | AF8: =IFERROR(VLOOKUP(Table1215[[#This Row],[Column2]],Table12[[Column2]:[Column54]],31,FALSE),"0") -> 0 | AG8: =IFERROR(VLOOKUP(Table1215[[#This Row],[Column2]],Table12[[Column2]:[Column54]],32,FALSE),"0") -> 0 | AH8: =IFERROR(VLOOKUP(Table1215[[#This Row],[Column2]],Table12[[Column2]:[Column54]],33,FALSE),"0") -> 0 | AI8: =IFERROR(VLOOKUP(Table1215[[#This Row],[Column2]],Table12[[Column2]:[Column54]],34,FALSE),"0") -> 0 | AJ8: =AVERAGE(Table1215[[#This Row],[Column31]],Table1215[[#This Row],[Column32]],Table1215[[#This Row],[Column33]]) -> 0 | AK8: =IFERROR(VLOOKUP(Table1215[[#This Row],[Column2]],Table12[[Column2]:[Column54]],36,FALSE),"0") -> 0 | AL8: =IFERROR(VLOOKUP(Table1215[[#This Row],[Column2]],Table12[[Column2]:[Column54]],37,FALSE),"0") -> 0 | AM8: =IFERROR(VLOOKUP(Table1215[[#This Row],[Column2]],Table12[[Column2]:[Column54]],38,FALSE),"0") -> 0 | AN8: =IFERROR(VLOOKUP(Table1215[[#This Row],[Column2]],Table12[[Column2]:[Column54]],39,FALSE),"0") -> 0 | AO8: =IFERROR(VLOOKUP(Table1215[[#This Row],[Column2]],Table12[[Column2]:[Column54]],40,FALSE),"0") -> 0 | AP8: =AVERAGE(Table1215[[#This Row],[Column37]],Table1215[[#This Row],[Column38]],Table1215[[#This Row],[Column40]]) -> #DIV/0! | AQ8: =IFERROR(VLOOKUP(Table1215[[#This Row],[Column2]],Table12[[Column2]:[Column54]],42,FALSE),"0") -> 0 | AR8: =IFERROR(VLOOKUP(Table1215[[#This Row],[Column2]],Table12[[Column2]:[Column54]],43,FALSE),"0") -> 0 | AS8: =IFERROR(VLOOKUP(Table1215[[#This Row],[Column2]],Table12[[Column2]:[Column54]],44,FALSE),"0") -> 0 | AT8: =IFERROR(VLOOKUP(Table1215[[#This Row],[Column2]],Table12[[Column2]:[Column54]],45,FALSE),"0") -> 0 | AU8: =IFERROR(VLOOKUP(Table1215[[#This Row],[Column2]],Table12[[Column2]:[Column54]],46,FALSE),"0") -> 0 | AV8: =Table1215[[#This Row],[Column43]] -> 0 | AW8: =IFERROR(VLOOKUP(Table1215[[#This Row],[Column2]],Table12[[Column2]:[Column54]],48,FALSE),"0") -> 0 | AX8: =IFERROR(VLOOKUP(Table1215[[#This Row],[Column2]],Table12[[Column2]:[Column54]],49,FALSE),"0") -> 0 | AY8: =IFERROR(VLOOKUP(Table1215[[#This Row],[Column2]],Table12[[Column2]:[Column54]],50,FALSE),"0") -> 0 | AZ8: =IFERROR(VLOOKUP(Table1215[[#This Row],[Column2]],Table12[[Column2]:[Column54]],51,FALSE),"0") -> 0 | BA8: =IFERROR(VLOOKUP(Table1215[[#This Row],[Column2]],Table12[[Column2]:[Column54]],52,FALSE),"0") -> 0 | BB8: =AVERAGE(Table1215[[#This Row],[Column52]],Table1215[[#This Row],[Column53]]) -> #DIV/0!
A9: 6 | B9: 2024JULB00006 | C9: Abhyuday Tripathi | D9: Male | E9: A | F9: =REPT(CHAR(160),10)&Working!$E10 -> A | G9: =IFERROR(VLOOKUP(Table1215[[#This Row],[Column2]],Table12[[Column2]:[Column54]],6,FALSE),"0") -> 0 | H9: =IFERROR(VLOOKUP(Table1215[[#This Row],[Column2]],Table12[[Column2]:[Column54]],7,FALSE),"0") -> 0 | I9: =IFERROR(VLOOKUP(Table1215[[#This Row],[Column2]],Table12[[Column2]:[Column54]],8,FALSE),"0") -> 4 | J9: =IFERROR(VLOOKUP(Table1215[[#This Row],[Column2]],Table12[[Column2]:[Column54]],9,FALSE),"0") -> 0 | K9: =IFERROR(VLOOKUP(Table1215[[#This Row],[Column2]],Table12[[Column2]:[Column54]],10,FALSE),"0") -> 0 | L9: =Table1215[[#This Row],[Column9]] -> 4 | M9: =IFERROR(VLOOKUP(Table1215[[#This Row],[Column2]],Table12[[Column2]:[Column54]],12,FALSE),"0") -> 0 | N9: =IFERROR(VLOOKUP(Table1215[[#This Row],[Column2]],Table12[[Column2]:[Column54]],13,FALSE),"0") -> 5 | O9: =IFERROR(VLOOKUP(Table1215[[#This Row],[Column2]],Table12[[Column2]:[Column54]],14,FALSE),"0") -> 4 | P9: =IFERROR(VLOOKUP(Table1215[[#This Row],[Column2]],Table12[[Column2]:[Column54]],10,FALSE),"0") -> 0 | Q9: =IFERROR(VLOOKUP(Table1215[[#This Row],[Column2]],Table12[[Column2]:[Column54]],16,FALSE),"0") -> 4 | R9: =AVERAGE(Table1215[[#This Row],[Column14]],Table1215[[#This Row],[Column15]],Table1215[[#This Row],[Column17]]) -> 4.3333333 | S9: =IFERROR(VLOOKUP(Table1215[[#This Row],[Column2]],Table12[[Column2]:[Column54]],18,FALSE),"0") -> 0 | T9: =IFERROR(VLOOKUP(Table1215[[#This Row],[Column2]],Table12[[Column2]:[Column54]],19,FALSE),"0") -> 0 | U9: =IFERROR(VLOOKUP(Table1215[[#This Row],[Column2]],Table12[[Column2]:[Column54]],20,FALSE),"0") -> 0 | V9: =IFERROR(VLOOKUP(Table1215[[#This Row],[Column2]],Table12[[Column2]:[Column54]],21,FALSE),"0") -> 0 | W9: =IFERROR(VLOOKUP(Table1215[[#This Row],[Column2]],Table12[[Column2]:[Column54]],22,FALSE),"0") -> 0 | X9: =Table1215[[#This Row],[Column19]] -> 0 | Y9: =IFERROR(VLOOKUP(Table1215[[#This Row],[Column2]],Table12[[Column2]:[Column54]],24,FALSE),"0") -> 5 | Z9: =IFERROR(VLOOKUP(Table1215[[#This Row],[Column2]],Table12[[Column2]:[Column54]],25,FALSE),"0") -> 0 | AA9: =IFERROR(VLOOKUP(Table1215[[#This Row],[Column2]],Table12[[Column2]:[Column54]],26,FALSE),"0") -> 0 | AB9: =IFERROR(VLOOKUP(Table1215[[#This Row],[Column2]],Table12[[Column2]:[Column54]],27,FALSE),"0") -> 0 | AC9: =IFERROR(VLOOKUP(Table1215[[#This Row],[Column2]],Table12[[Column2]:[Column54]],28,FALSE),"0") -> 0 | AD9: =Table1215[[#This Row],[Column25]] -> 5 | AE9: =IFERROR(VLOOKUP(Table1215[[#This Row],[Column2]],Table12[[Column2]:[Column54]],30,FALSE),"0") -> 0 | AF9: =IFERROR(VLOOKUP(Table1215[[#This Row],[Column2]],Table12[[Column2]:[Column54]],31,FALSE),"0") -> 0 | AG9: =IFERROR(VLOOKUP(Table1215[[#This Row],[Column2]],Table12[[Column2]:[Column54]],32,FALSE),"0") -> 0 | AH9: =IFERROR(VLOOKUP(Table1215[[#This Row],[Column2]],Table12[[Column2]:[Column54]],33,FALSE),"0") -> 0 | AI9: =IFERROR(VLOOKUP(Table1215[[#This Row],[Column2]],Table12[[Column2]:[Column54]],34,FALSE),"0") -> 0 | AJ9: =AVERAGE(Table1215[[#This Row],[Column31]],Table1215[[#This Row],[Column32]],Table1215[[#This Row],[Column33]]) -> 0 | AK9: =IFERROR(VLOOKUP(Table1215[[#This Row],[Column2]],Table12[[Column2]:[Column54]],36,FALSE),"0") -> 5 | AL9: =IFERROR(VLOOKUP(Table1215[[#This Row],[Column2]],Table12[[Column2]:[Column54]],37,FALSE),"0") -> 5 | AM9: =IFERROR(VLOOKUP(Table1215[[#This Row],[Column2]],Table12[[Column2]:[Column54]],38,FALSE),"0") -> 0 | AN9: =IFERROR(VLOOKUP(Table1215[[#This Row],[Column2]],Table12[[Column2]:[Column54]],39,FALSE),"0") -> 5 | AO9: =IFERROR(VLOOKUP(Table1215[[#This Row],[Column2]],Table12[[Column2]:[Column54]],40,FALSE),"0") -> 0 | AP9: =AVERAGE(Table1215[[#This Row],[Column37]],Table1215[[#This Row],[Column38]],Table1215[[#This Row],[Column40]]) -> 5 | AQ9: =IFERROR(VLOOKUP(Table1215[[#This Row],[Column2]],Table12[[Column2]:[Column54]],42,FALSE),"0") -> 5 | AR9: =IFERROR(VLOOKUP(Table1215[[#This Row],[Column2]],Table12[[Column2]:[Column54]],43,FALSE),"0") -> 0 | AS9: =IFERROR(VLOOKUP(Table1215[[#This Row],[Column2]],Table12[[Column2]:[Column54]],44,FALSE),"0") -> 0 | AT9: =IFERROR(VLOOKUP(Table1215[[#This Row],[Column2]],Table12[[Column2]:[Column54]],45,FALSE),"0") -> 0 | AU9: =IFERROR(VLOOKUP(Table1215[[#This Row],[Column2]],Table12[[Column2]:[Column54]],46,FALSE),"0") -> 0 | AV9: =Table1215[[#This Row],[Column43]] -> 5 | AW9: =IFERROR(VLOOKUP(Table1215[[#This Row],[Column2]],Table12[[Column2]:[Column54]],48,FALSE),"0") -> 0 | AX9: =IFERROR(VLOOKUP(Table1215[[#This Row],[Column2]],Table12[[Column2]:[Column54]],49,FALSE),"0") -> 0 | AY9: =IFERROR(VLOOKUP(Table1215[[#This Row],[Column2]],Table12[[Column2]:[Column54]],50,FALSE),"0") -> 0 | AZ9: =IFERROR(VLOOKUP(Table1215[[#This Row],[Column2]],Table12[[Column2]:[Column54]],51,FALSE),"0") -> 5 | BA9: =IFERROR(VLOOKUP(Table1215[[#This Row],[Column2]],Table12[[Column2]:[Column54]],52,FALSE),"0") -> 5 | BB9: =AVERAGE(Table1215[[#This Row],[Column52]],Table1215[[#This Row],[Column53]]) -> 5
