Workbook

Sheet  PEP Grade
B1: 3 | C1: 4 | D1: 1 | E1: 2
A2: Sr # | B2: Gender | C2: Section | D2: RN | E2: Student name | F2: HPS | G2: Grade | H2: Afflictions | L2: Result
H3: Level 0 | I3: Level 1 | J3: Level 2 | K3: Level 3
A4: 1 | B4: Female | C4: A | D4: 2024JULB00001 | E4: A Divya Sree | F4: =AVERAGE('HPS grading'!F4,'HPS grading'!K4,'HPS grading'!P4,'HPS grading'!U4) -> 54.637454 | G4: {=_xlfn.IFS(F4>=80,"A+",F4>=70,"A",F4=60,"B+",F4>=50,"B",F4>=40,"C+",F4>=30,"C",F4>=20,"D",F4<20,"E")} -> B | H4: =IF('HPS grading'!H4&'HPS grading'!I4="ClearedCleared","None",IF('HPS grading'!H4="NC","Persona ","") &IF('HPS grading'!I4="NC","Wellness ","")) -> None | I4: =IF('HPS grading'!M4&'HPS grading'!N4="ClearedCleared","None",IF('HPS grading'!M4="NC","Persona ","") &IF('HPS grading'!N4="NC","Wellness","")) -> Wellness | J4: =IF('HPS grading'!R4&'HPS grading'!S4="ClearedCleared","None",IF('HPS grading'!R4="NC","Persona ","") &IF('HPS grading'!S4="NC","Wellness ","")) -> None | K4: =IF('HPS grading'!W4&'HPS grading'!X4="ClearedCleared","None",IF('HPS grading'!W4="NC","Persona ","") &IF('HPS grading'!X4="NC","Wellness ","")) -> Wellness | L4: =IF(COUNTIF(H4:K4,"None")=4,"Passed","With Held") -> With Held | M4: =IF($L4<>"With Held","",_xlfn.TEXTJOIN(", ",TRUE,IF(TRIM($H4)<>"None","Level 0 - "&SUBSTITUTE(TRIM($H4)," "," & "), ""),IF(TRIM($I4)<>"None","Level 1 - "&SUBSTITUTE(TRIM($I4)," "," & "), ""),IF(TRIM($J4)<>"None","Level 2 - "&SUBSTITUTE(TRIM($J4)," "," & "), ""),IF(TRIM($K4)<>"None","Level 3 - "&SUBSTITUTE(TRIM($K4)," "," & "), ""))) -> Level 1 - Wellness, Level 3 - Wellness
A5: 2 | B5: Male | C5: A | D5: 2024JULB00002 | E5: Aaditya K | F5: =AVERAGE('HPS grading'!F5,'HPS grading'!K5,'HPS grading'!P5,'HPS grading'!U5) -> 54.432632 | G5: {=_xlfn.IFS(F5>=80,"A+",F5>=70,"A",F5=60,"B+",F5>=50,"B",F5>=40,"C+",F5>=30,"C",F5>=20,"D",F5<20,"E")} -> B | H5: =IF('HPS grading'!H5&'HPS grading'!I5="ClearedCleared","None",IF('HPS grading'!H5="NC","Persona ","") &IF('HPS grading'!I5="NC","Wellness ","")) -> Persona | I5: =IF('HPS grading'!M5&'HPS grading'!N5="ClearedCleared","None",IF('HPS grading'!M5="NC","Persona ","") &IF('HPS grading'!N5="NC","Wellness","")) -> None | J5: =IF('HPS grading'!R5&'HPS grading'!S5="ClearedCleared","None",IF('HPS grading'!R5="NC","Persona ","") &IF('HPS grading'!S5="NC","Wellness ","")) -> Persona Wellness | K5: =IF('HPS grading'!W5&'HPS grading'!X5="ClearedCleared","None",IF('HPS grading'!W5="NC","Persona ","") &IF('HPS grading'!X5="NC","Wellness ","")) -> None | L5: =IF(COUNTIF(H5:K5,"None")=4,"Passed","With Held") -> With Held | M5: =IF($L5<>"With Held","",_xlfn.TEXTJOIN(", ",TRUE,IF(TRIM($H5)<>"None","Level 0 - "&SUBSTITUTE(TRIM($H5)," "," & "), ""),IF(TRIM($I5)<>"None","Level 1 - "&SUBSTITUTE(TRIM($I5)," "," & "), ""),IF(TRIM($J5)<>"None","Level 2 - "&SUBSTITUTE(TRIM($J5)," "," & "), ""),IF(TRIM($K5)<>"None","Level 3 - "&SUBSTITUTE(TRIM($K5)," "," & "), ""))) -> Level 0 - Persona, Level 2 - Persona & Wellness
A6: 3 | B6: Female | C6: A | D6: 2024JULB00003 | E6: Aanchal Sapra | F6: =AVERAGE('HPS grading'!F6,'HPS grading'!K6,'HPS grading'!P6,'HPS grading'!U6) -> 43.126134 | G6: {=_xlfn.IFS(F6>=80,"A+",F6>=70,"A",F6=60,"B+",F6>=50,"B",F6>=40,"C+",F6>=30,"C",F6>=20,"D",F6<20,"E")} -> C+ | H6: =IF('HPS grading'!H6&'HPS grading'!I6="ClearedCleared","None",IF('HPS grading'!H6="NC","Persona ","") &IF('HPS grading'!I6="NC","Wellness ","")) -> None | I6: =IF('HPS grading'!M6&'HPS grading'!N6="ClearedCleared","None",IF('HPS grading'!M6="NC","Persona ","") &IF('HPS grading'!N6="NC","Wellness","")) -> Wellness | J6: =IF('HPS grading'!R6&'HPS grading'!S6="ClearedCleared","None",IF('HPS grading'!R6="NC","Persona ","") &IF('HPS grading'!S6="NC","Wellness ","")) -> Persona Wellness | K6: =IF('HPS grading'!W6&'HPS grading'!X6="ClearedCleared","None",IF('HPS grading'!W6="NC","Persona ","") &IF('HPS grading'!X6="NC","Wellness ","")) -> Wellness | L6: =IF(COUNTIF(H6:K6,"None")=4,"Passed","With Held") -> With Held | M6: =IF($L6<>"With Held","",_xlfn.TEXTJOIN(", ",TRUE,IF(TRIM($H6)<>"None","Level 0 - "&SUBSTITUTE(TRIM($H6)," "," & "), ""),IF(TRIM($I6)<>"None","Level 1 - "&SUBSTITUTE(TRIM($I6)," "," & "), ""),IF(TRIM($J6)<>"None","Level 2 - "&SUBSTITUTE(TRIM($J6)," "," & "), ""),IF(TRIM($K6)<>"None","Level 3 - "&SUBSTITUTE(TRIM($K6)," "," & "), ""))) -> Level 1 - Wellness, Level 2 - Persona & Wellness, Level 3 - Wellness
A7: 4 | B7: Male | C7: A | D7: 2024JULB00004 | E7: Abhinav B | F7: =AVERAGE('HPS grading'!F7,'HPS grading'!K7,'HPS grading'!P7,'HPS grading'!U7) -> 53.226316 | G7: {=_xlfn.IFS(F7>=80,"A+",F7>=70,"A",F7=60,"B+",F7>=50,"B",F7>=40,"C+",F7>=30,"C",F7>=20,"D",F7<20,"E")} -> B | H7: =IF('HPS grading'!H7&'HPS grading'!I7="ClearedCleared","None",IF('HPS grading'!H7="NC","Persona ","") &IF('HPS grading'!I7="NC","Wellness ","")) -> None | I7: =IF('HPS grading'!M7&'HPS grading'!N7="ClearedCleared","None",IF('HPS grading'!M7="NC","Persona ","") &IF('HPS grading'!N7="NC","Wellness","")) -> Wellness | J7: =IF('HPS grading'!R7&'HPS grading'!S7="ClearedCleared","None",IF('HPS grading'!R7="NC","Persona ","") &IF('HPS grading'!S7="NC","Wellness ","")) -> Persona Wellness | K7: =IF('HPS grading'!W7&'HPS grading'!X7="ClearedCleared","None",IF('HPS grading'!W7="NC","Persona ","") &IF('HPS grading'!X7="NC","Wellness ","")) -> Wellness | L7: =IF(COUNTIF(H7:K7,"None")=4,"Passed","With Held") -> With Held | M7: =IF($L7<>"With Held","",_xlfn.TEXTJOIN(", ",TRUE,IF(TRIM($H7)<>"None","Level 0 - "&SUBSTITUTE(TRIM($H7)," "," & "), ""),IF(TRIM($I7)<>"None","Level 1 - "&SUBSTITUTE(TRIM($I7)," "," & "), ""),IF(TRIM($J7)<>"None","Level 2 - "&SUBSTITUTE(TRIM($J7)," "," & "), ""),IF(TRIM($K7)<>"None","Level 3 - "&SUBSTITUTE(TRIM($K7)," "," & "), ""))) -> Level 1 - Wellness, Level 2 - Persona & Wellness, Level 3 - Wellness
A8: 5 | B8: Male | C8: D | D8: 2024JULB00005 | E8: Abhirup Choudhury | F8: =AVERAGE('HPS grading'!F8,'HPS grading'!K8,'HPS grading'!P8,'HPS grading'!U8) -> 11.437222 | G8: {=_xlfn.IFS(F8>=80,"A+",F8>=70,"A",F8=60,"B+",F8>=50,"B",F8>=40,"C+",F8>=30,"C",F8>=20,"D",F8<20,"E")} -> E | H8: =IF('HPS grading'!H8&'HPS grading'!I8="ClearedCleared","None",IF('HPS grading'!H8="NC","Persona ","") &IF('HPS grading'!I8="NC","Wellness ","")) -> Persona Wellness | I8: =IF('HPS grading'!M8&'HPS grading'!N8="ClearedCleared","None",IF('HPS grading'!M8="NC","Persona ","") &IF('HPS grading'!N8="NC","Wellness","")) -> Persona Wellness | J8: =IF('HPS grading'!R8&'HPS grading'!S8="ClearedCleared","None",IF('HPS grading'!R8="NC","Persona ","") &IF('HPS grading'!S8="NC","Wellness ","")) -> Wellness | K8: =IF('HPS grading'!W8&'HPS grading'!X8="ClearedCleared","None",IF('HPS grading'!W8="NC","Persona ","") &IF('HPS grading'!X8="NC","Wellness ","")) -> Persona Wellness | L8: =IF(COUNTIF(H8:K8,"None")=4,"Passed","With Held") -> With Held | M8: =IF($L8<>"With Held","",_xlfn.TEXTJOIN(", ",TRUE,IF(TRIM($H8)<>"None","Level 0 - "&SUBSTITUTE(TRIM($H8)," "," & "), ""),IF(TRIM($I8)<>"None","Level 1 - "&SUBSTITUTE(TRIM($I8)," "," & "), ""),IF(TRIM($J8)<>"None","Level 2 - "&SUBSTITUTE(TRIM($J8)," "," & "), ""),IF(TRIM($K8)<>"None","Level 3 - "&SUBSTITUTE(TRIM($K8)," "," & "), ""))) -> Level 0 - Persona & Wellness, Level 1 - Persona & Wellness, Level 2 - Wellness, Level 3 - Persona & Wellness
A9: 6 | B9: Male | C9: A | D9: 2024JULB00006 | E9: Abhyuday Tripathi | F9: =AVERAGE('HPS grading'!F9,'HPS grading'!K9,'HPS grading'!P9,'HPS grading'!U9) -> 60.344947 | G9: {=_xlfn.IFS(F9>=80,"A+",F9>=70,"A",F9=60,"B+",F9>=50,"B",F9>=40,"C+",F9>=30,"C",F9>=20,"D",F9<20,"E")} -> B | H9: =IF('HPS grading'!H9&'HPS grading'!I9="ClearedCleared","None",IF('HPS grading'!H9="NC","Persona ","") &IF('HPS grading'!I9="NC","Wellness ","")) -> None | I9: =IF('HPS grading'!M9&'HPS grading'!N9="ClearedCleared","None",IF('HPS grading'!M9="NC","Persona ","") &IF('HPS grading'!N9="NC","Wellness","")) -> None | J9: =IF('HPS grading'!R9&'HPS grading'!S9="ClearedCleared","None",IF('HPS grading'!R9="NC","Persona ","") &IF('HPS grading'!S9="NC","Wellness ","")) -> Wellness | K9: =IF('HPS grading'!W9&'HPS grading'!X9="ClearedCleared","None",IF('HPS grading'!W9="NC","Persona ","") &IF('HPS grading'!X9="NC","Wellness ","")) -> None | L9: =IF(COUNTIF(H9:K9,"None")=4,"Passed","With Held") -> With Held | M9: =IF($L9<>"With Held","",_xlfn.TEXTJOIN(", ",TRUE,IF(TRIM($H9)<>"None","Level 0 - "&SUBSTITUTE(TRIM($H9)," "," & "), ""),IF(TRIM($I9)<>"None","Level 1 - "&SUBSTITUTE(TRIM($I9)," "," & "), ""),IF(TRIM($J9)<>"None","Level 2 - "&SUBSTITUTE(TRIM($J9)," "," & "), ""),IF(TRIM($K9)<>"None","Level 3 - "&SUBSTITUTE(TRIM($K9)," "," & "), ""))) -> Level 2 - Wellness
A10: 7 | B10: Male | C10: A | D10: 2024JULB00007 | E10: Adarsh G | F10: =AVERAGE('HPS grading'!F10,'HPS grading'!K10,'HPS grading'!P10,'HPS grading'!U10) -> 55.147259 | G10: {=_xlfn.IFS(F10>=80,"A+",F10>=70,"A",F10=60,"B+",F10>=50,"B",F10>=40,"C+",F10>=30,"C",F10>=20,"D",F10<20,"E")} -> B | H10: =IF('HPS grading'!H10&'HPS grading'!I10="ClearedCleared","None",IF('HPS grading'!H10="NC","Persona ","") &IF('HPS grading'!I10="NC","Wellness ","")) -> None | I10: =IF('HPS grading'!M10&'HPS grading'!N10="ClearedCleared","None",IF('HPS grading'!M10="NC","Persona ","") &IF('HPS grading'!N10="NC","Wellness","")) -> Wellness | J10: =IF('HPS grading'!R10&'HPS grading'!S10="ClearedCleared","None",IF('HPS grading'!R10="NC","Persona ","") &IF('HPS grading'!S10="NC","Wellness ","")) -> Wellness | K10: =IF('HPS grading'!W10&'HPS grading'!X10="ClearedCleared","None",IF('HPS grading'!W10="NC","Persona ","") &IF('HPS grading'!X10="NC","Wellness ","")) -> Wellness | L10: =IF(COUNTIF(H10:K10,"None")=4,"Passed","With Held") -> With Held | M10: =IF($L10<>"With Held","",_xlfn.TEXTJOIN(", ",TRUE,IF(TRIM($H10)<>"None","Level 0 - "&SUBSTITUTE(TRIM($H10)," "," & "), ""),IF(TRIM($I10)<>"None","Level 1 - "&SUBSTITUTE(TRIM($I10)," "," & "), ""),IF(TRIM($J10)<>"None","Level 2 - "&SUBSTITUTE(TRIM($J10)," "," & "), ""),IF(TRIM($K10)<>"None","Level 3 - "&SUBSTITUTE(TRIM($K10)," "," & "), ""))) -> Level 1 - Wellness, Level 2 - Wellness, Level 3 - Wellness
A11: 8 | B11: Male | C11: C | D11: 2024JULB00008 | E11: Adarsh Raj Barman | F11: =AVERAGE('HPS grading'!F11,'HPS grading'!K11,'HPS grading'!P11,'HPS grading'!U11) -> 56.750689 | G11: {=_xlfn.IFS(F11>=80,"A+",F11>=70,"A",F11=60,"B+",F11>=50,"B",F11>=40,"C+",F11>=30,"C",F11>=20,"D",F11<20,"E")} -> B | H11: =IF('HPS grading'!H11&'HPS grading'!I11="ClearedCleared","None",IF('HPS grading'!H11="NC","Persona ","") &IF('HPS grading'!I11="NC","Wellness ","")) -> None | I11: =IF('HPS grading'!M11&'HPS grading'!N11="ClearedCleared","None",IF('HPS grading'!M11="NC","Persona ","") &IF('HPS grading'!N11="NC","Wellness","")) -> None | J11: =IF('HPS grading'!R11&'HPS grading'!S11="ClearedCleared","None",IF('HPS grading'!R11="NC","Persona ","") &IF('HPS grading'!S11="NC","Wellness ","")) -> None | K11: =IF('HPS grading'!W11&'HPS grading'!X11="ClearedCleared","None",IF('HPS grading'!W11="NC","Persona ","") &IF('HPS grading'!X11="NC","Wellness ","")) -> None | L11: =IF(COUNTIF(H11:K11,"None")=4,"Passed","With Held") -> Passed | M11: =IF($L11<>"With Held","",_xlfn.TEXTJOIN(", ",TRUE,IF(TRIM($H11)<>"None","Level 0 - "&SUBSTITUTE(TRIM($H11)," "," & "), ""),IF(TRIM($I11)<>"None","Level 1 - "&SUBSTITUTE(TRIM($I11)," "," & "), ""),IF(TRIM($J11)<>"None","Level 2 - "&SUBSTITUTE(TRIM($J11)," "," & "), ""),IF(TRIM($K11)<>"None","Level 3 - "&SUBSTITUTE(TRIM($K11)," "," & "), "")))
A12: 9 | B12: Female | C12: A | D12: 2024JULB00009 | E12: Aditi Kumari | F12: =AVERAGE('HPS grading'!F12,'HPS grading'!K12,'HPS grading'!P12,'HPS grading'!U12) -> 58.83248 | G12: {=_xlfn.IFS(F12>=80,"A+",F12>=70,"A",F12=60,"B+",F12>=50,"B",F12>=40,"C+",F12>=30,"C",F12>=20,"D",F12<20,"E")} -> B | H12: =IF('HPS grading'!H12&'HPS grading'!I12="ClearedCleared","None",IF('HPS grading'!H12="NC","Persona ","") &IF('HPS grading'!I12="NC","Wellness ","")) -> None | I12: =IF('HPS grading'!M12&'HPS grading'!N12="ClearedCleared","None",IF('HPS grading'!M12="NC","Persona ","") &IF('HPS grading'!N12="NC","Wellness","")) -> None | J12: =IF('HPS grading'!R12&'HPS grading'!S12="ClearedCleared","None",IF('HPS grading'!R12="NC","Persona ","") &IF('HPS grading'!S12="NC","Wellness ","")) -> None | K12: =IF('HPS grading'!W12&'HPS grading'!X12="ClearedCleared","None",IF('HPS grading'!W12="NC","Persona ","") &IF('HPS grading'!X12="NC","Wellness ","")) -> None | L12: =IF(COUNTIF(H12:K12,"None")=4,"Passed","With Held") -> Passed | M12: =IF($L12<>"With Held","",_xlfn.TEXTJOIN(", ",TRUE,IF(TRIM($H12)<>"None","Level 0 - "&SUBSTITUTE(TRIM($H12)," "," & "), ""),IF(TRIM($I12)<>"None","Level 1 - "&SUBSTITUTE(TRIM($I12)," "," & "), ""),IF(TRIM($J12)<>"None","Level 2 - "&SUBSTITUTE(TRIM($J12)," "," & "), ""),IF(TRIM($K12)<>"None","Level 3 - "&SUBSTITUTE(TRIM($K12)," "," & "), "")))
A13: 10 | B13: Male | C13: A | D13: 2024JULB00012 | E13: Akarsh Narain | F13: =AVERAGE('HPS grading'!F13,'HPS grading'!K13,'HPS grading'!P13,'HPS grading'!U13) -> 57.194292 | G13: {=_xlfn.IFS(F13>=80,"A+",F13>=70,"A",F13=60,"B+",F13>=50,"B",F13>=40,"C+",F13>=30,"C",F13>=20,"D",F13<20,"E")} -> B | H13: =IF('HPS grading'!H13&'HPS grading'!I13="ClearedCleared","None",IF('HPS grading'!H13="NC","Persona ","") &IF('HPS grading'!I13="NC","Wellness ","")) -> None | I13: =IF('HPS grading'!M13&'HPS grading'!N13="ClearedCleared","None",IF('HPS grading'!M13="NC","Persona ","") &IF('HPS grading'!N13="NC","Wellness","")) -> Wellness | J13: =IF('HPS grading'!R13&'HPS grading'!S13="ClearedCleared","None",IF('HPS grading'!R13="NC","Persona ","") &IF('HPS grading'!S13="NC","Wellness ","")) -> None | K13: =IF('HPS grading'!W13&'HPS grading'!X13="ClearedCleared","None",IF('HPS grading'!W13="NC","Persona ","") &IF('HPS grading'!X13="NC","Wellness ","")) -> Wellness | L13: =IF(COUNTIF(H13:K13,"None")=4,"Passed","With Held") -> With Held | M13: =IF($L13<>"With Held","",_xlfn.TEXTJOIN(", ",TRUE,IF(TRIM($H13)<>"None","Level 0 - "&SUBSTITUTE(TRIM($H13)," "," & "), ""),IF(TRIM($I13)<>"None","Level 1 - "&SUBSTITUTE(TRIM($I13)," "," & "), ""),IF(TRIM($J13)<>"None","Level 2 - "&SUBSTITUTE(TRIM($J13)," "," & "), ""),IF(TRIM($K13)<>"None","Level 3 - "&SUBSTITUTE(TRIM($K13)," "," & "), ""))) -> Level 1 - Wellness, Level 3 - Wellness
A14: 11 | B14: Male | C14: B | D14: 2024JULB00013 | E14: Akshat Singh | F14: =AVERAGE('HPS grading'!F14,'HPS grading'!K14,'HPS grading'!P14,'HPS grading'!U14) -> 52.048089 | G14: {=_xlfn.IFS(F14>=80,"A+",F14>=70,"A",F14=60,"B+",F14>=50,"B",F14>=40,"C+",F14>=30,"C",F14>=20,"D",F14<20,"E")} -> B | H14: =IF('HPS grading'!H14&'HPS grading'!I14="ClearedCleared","None",IF('HPS grading'!H14="NC","Persona ","") &IF('HPS grading'!I14="NC","Wellness ","")) -> None | I14: =IF('HPS grading'!M14&'HPS grading'!N14="ClearedCleared","None",IF('HPS grading'!M14="NC","Persona ","") &IF('HPS grading'!N14="NC","Wellness","")) -> None | J14: =IF('HPS grading'!R14&'HPS grading'!S14="ClearedCleared","None",IF('HPS grading'!R14="NC","Persona ","") &IF('HPS grading'!S14="NC","Wellness ","")) -> None | K14: =IF('HPS grading'!W14&'HPS grading'!X14="ClearedCleared","None",IF('HPS grading'!W14="NC","Persona ","") &IF('HPS grading'!X14="NC","Wellness ","")) -> None | L14: =IF(COUNTIF(H14:K14,"None")=4,"Passed","With Held") -> Passed | M14: =IF($L14<>"With Held","",_xlfn.TEXTJOIN(", ",TRUE,IF(TRIM($H14)<>"None","Level 0 - "&SUBSTITUTE(TRIM($H14)," "," & "), ""),IF(TRIM($I14)<>"None","Level 1 - "&SUBSTITUTE(TRIM($I14)," "," & "), ""),IF(TRIM($J14)<>"None","Level 2 - "&SUBSTITUTE(TRIM($J14)," "," & "), ""),IF(TRIM($K14)<>"None","Level 3 - "&SUBSTITUTE(TRIM($K14)," "," & "), "")))
A15: 12 | B15: Male | C15: B | D15: 2024JULB00014 | E15: Amal Shibu Balan | F15: =AVERAGE('HPS grading'!F15,'HPS grading'!K15,'HPS grading'!P15,'HPS grading'!U15) -> 51.480304 | G15: {=_xlfn.IFS(F15>=80,"A+",F15>=70,"A",F15=60,"B+",F15>=50,"B",F15>=40,"C+",F15>=30,"C",F15>=20,"D",F15<20,"E")} -> B | H15: =IF('HPS grading'!H15&'HPS grading'!I15="ClearedCleared","None",IF('HPS grading'!H15="NC","Persona ","") &IF('HPS grading'!I15="NC","Wellness ","")) -> None | I15: =IF('HPS grading'!M15&'HPS grading'!N15="ClearedCleared","None",IF('HPS grading'!M15="NC","Persona ","") &IF('HPS grading'!N15="NC","Wellness","")) -> Wellness | J15: =IF('HPS grading'!R15&'HPS grading'!S15="ClearedCleared","None",IF('HPS grading'!R15="NC","Persona ","") &IF('HPS grading'!S15="NC","Wellness ","")) -> None | K15: =IF('HPS grading'!W15&'HPS grading'!X15="ClearedCleared","None",IF('HPS grading'!W15="NC","Persona ","") &IF('HPS grading'!X15="NC","Wellness ","")) -> None | L15: =IF(COUNTIF(H15:K15,"None")=4,"Passed","With Held") -> With Held | M15: =IF($L15<>"With Held","",_xlfn.TEXTJOIN(", ",TRUE,IF(TRIM($H15)<>"None","Level 0 - "&SUBSTITUTE(TRIM($H15)," "," & "), ""),IF(TRIM($I15)<>"None","Level 1 - "&SUBSTITUTE(TRIM($I15)," "," & "), ""),IF(TRIM($J15)<>"None","Level 2 - "&SUBSTITUTE(TRIM($J15)," "," & "), ""),IF(TRIM($K15)<>"None","Level 3 - "&SUBSTITUTE(TRIM($K15)," "," & "), ""))) -> Level 1 - Wellness
... A231: 228 | B231: Male | C231: D | D231: 2024JULB00273 | E231: Harshit Gopawat | F231: =AVERAGE('HPS grading'!F231,'HPS grading'!K231,'HPS grading'!P231,'HPS grading'!U231) -> 15.353796 | G231: {=_xlfn.IFS(F231>=80,"A+",F231>=70,"A",F231=60,"B+",F231>=50,"B",F231>=40,"C+",F231>=30,"C",F231>=20,"D",F231<20,"E")} -> E | H231: =IF('HPS grading'!H231&'HPS grading'!I231="ClearedCleared","None",IF('HPS grading'!H231="NC","Persona ","") &IF('HPS grading'!I231="NC","Wellness ","")) -> Persona Wellness | I231: =IF('HPS grading'!M231&'HPS grading'!N231="ClearedCleared","None",IF('HPS grading'!M231="NC","Persona ","") &IF('HPS grading'!N231="NC","Wellness","")) -> Persona Wellness | J231: =IF('HPS grading'!R231&'HPS grading'!S231="ClearedCleared","None",IF('HPS grading'!R231="NC","Persona ","") &IF('HPS grading'!S231="NC","Wellness ","")) -> Persona Wellness | K231: =IF('HPS grading'!W231&'HPS grading'!X231="ClearedCleared","None",IF('HPS grading'!W231="NC","Persona ","") &IF('HPS grading'!X231="NC","Wellness ","")) -> Persona Wellness | L231: =IF(COUNTIF(H231:K231,"None")=4,"Passed","With Held") -> With Held | M231: =IF($L231<>"With Held","",_xlfn.TEXTJOIN(", ",TRUE,IF(TRIM($H231)<>"None","Level 0 - "&SUBSTITUTE(TRIM($H231)," "," & "), ""),IF(TRIM($I231)<>"None","Level 1 - "&SUBSTITUTE(TRIM($I231)," "," & "), ""),IF(TRIM($J231)<>"None","Level 2 - "&SUBSTITUTE(TRIM($J231)," "," & "), ""),IF(TRIM($K231)<>"None","Level 3 - "&SUBSTITUTE(TRIM($K231)," "," & "), ""))) -> Level 0 - Persona & Wellness, Level 1 - Persona & Wellness, Level 2 - Persona & Wellness, Level 3 - Persona & Wellness
F234: Cleared | H234: =COUNTIF($H$4:$H$231,"None") -> 133 | I234: =COUNTIF($I$4:$I$231,"None") -> 51 | J234: =COUNTIF($J$4:$J$231,"None") -> 77 | K234: =COUNTIF($K$4:$K$231,"None") -> 89
F235: Persona | H235: =COUNTIF($H$4:$H$231,"Persona ") -> 52 | I235: =COUNTIF($I$4:$I$231,"Persona ") -> 0 | J235: =COUNTIF($J$4:$J$231,"Persona ") -> 16 | K235: =COUNTIF($K$4:$K$231,"Persona ") -> 13
F236: Wellness | H236: =COUNTIF($H$4:$H$231,"Wellness ") -> 30 | I236: =COUNTIF($I$4:$I$231,"Wellness ") -> 0 | J236: =COUNTIF($J$4:$J$231,"Wellness ") -> 98 | K236: =COUNTIF($K$4:$K$231,"Wellness ") -> 105
F237: Persona & Wellness | H237: =COUNTIF($H$4:$H$231,"Persona Wellness ") -> 13 | I237: =COUNTIF($I$4:$I$231,"Persona Wellness ") -> 0 | J237: =COUNTIF($J$4:$J$231,"Persona Wellness ") -> 37 | K237: =COUNTIF($K$4:$K$231,"Persona Wellness ") -> 21
F238: Total | H238: =SUM(H234:H237) -> 228 | I238: =SUM(I234:I237) -> 51 | J238: =SUM(J234:J237) -> 228 | K238: =SUM(K234:K237) -> 228

Sheet PEP Grade Final
A1: Sr # | B1: Gender | C1: Section | D1: RN | E1: Student name | F1: Holistic Personality Score All Levels | J1: HPS Grade | M1: Afflictions
F2: Level 0 | G2: Level 1 | H2: Level 2 | I2: Level 3 | J2: FINAL HPS | K2: Grade | L2: Result
A3: 1 | B3: Female | C3: A | D3: 2024JULB00001 | E3: A Divya Sree | F3: ='HPS grading'!K4 -> 53.71 | G3: ='HPS grading'!P4 -> 55.527778 | H3: ='HPS grading'!U4 -> 53.575926 | I3: ='HPS grading'!Z4 -> 54.637454 | J3: =AVERAGE(F3,G3,H3,I3) -> 54.362789 | K3: {=_xlfn.IFS(J3>=80,"A+",J3>=70,"A",J3=60,"B+",J3>=50,"B",J3>=40,"C+",J3>=30,"C",J3>=20,"D",J3<20,"E")} -> B | L3: =' PEP Grade'!L4 -> With Held | M3: =' PEP Grade'!M4 -> Level 1 - Wellness, Level 3 - Wellness
A4: 2 | B4: Male | C4: A | D4: 2024JULB00002 | E4: Aaditya K | F4: ='HPS grading'!K5 -> 65.319048 | G4: ='HPS grading'!P5 -> 36.357778 | H4: ='HPS grading'!U5 -> 58.859259 | I4: ='HPS grading'!Z5 -> 54.432632 | J4: =AVERAGE(F4,G4,H4,I4) -> 53.742179 | K4: {=_xlfn.IFS(J4>=80,"A+",J4>=70,"A",J4=60,"B+",J4>=50,"B",J4>=40,"C+",J4>=30,"C",J4>=20,"D",J4<20,"E")} -> B | L4: =' PEP Grade'!L5 -> With Held | M4: =' PEP Grade'!M5 -> Level 0 - Persona, Level 2 - Persona & Wellness
A5: 3 | B5: Female | C5: A | D5: 2024JULB00003 | E5: Aanchal Sapra | F5: ='HPS grading'!K6 -> 44.435833 | G5: ='HPS grading'!P6 -> 35.117778 | H5: ='HPS grading'!U6 -> 38.742593 | I5: ='HPS grading'!Z6 -> 43.126134 | J5: =AVERAGE(F5,G5,H5,I5) -> 40.355584 | K5: {=_xlfn.IFS(J5>=80,"A+",J5>=70,"A",J5=60,"B+",J5>=50,"B",J5>=40,"C+",J5>=30,"C",J5>=20,"D",J5<20,"E")} -> C+ | L5: =' PEP Grade'!L6 -> With Held | M5: =' PEP Grade'!M6 -> Level 1 - Wellness, Level 2 - Persona & Wellness, Level 3 - Wellness
A6: 4 | B6: Male | C6: A | D6: 2024JULB00004 | E6: Abhinav B | F6: ='HPS grading'!K7 -> 46.654524 | G6: ='HPS grading'!P7 -> 46.437778 | H6: ='HPS grading'!U7 -> 55.72963 | I6: ='HPS grading'!Z7 -> 53.226316 | J6: =AVERAGE(F6,G6,H6,I6) -> 50.512062 | K6: {=_xlfn.IFS(J6>=80,"A+",J6>=70,"A",J6=60,"B+",J6>=50,"B",J6>=40,"C+",J6>=30,"C",J6>=20,"D",J6<20,"E")} -> B | L6: =' PEP Grade'!L7 -> With Held | M6: =' PEP Grade'!M7 -> Level 1 - Wellness, Level 2 - Persona & Wellness, Level 3 - Wellness
A7: 5 | B7: Male | C7: D | D7: 2024JULB00005 | E7: Abhirup Choudhury | F7: ='HPS grading'!K8 -> 3.2 | G7: ='HPS grading'!P8 -> 29.004444 | H7: ='HPS grading'!U8 -> 6.0444444 | I7: ='HPS grading'!Z8 -> 11.437222 | J7: =AVERAGE(F7,G7,H7,I7) -> 12.421528 | K7: {=_xlfn.IFS(J7>=80,"A+",J7>=70,"A",J7=60,"B+",J7>=50,"B",J7>=40,"C+",J7>=30,"C",J7>=20,"D",J7<20,"E")} -> E | L7: =' PEP Grade'!L8 -> With Held | M7: =' PEP Grade'!M8 -> Level 0 - Persona & Wellness, Level 1 - Persona & Wellness, Level 2 - Wellness, Level 3 - Persona & Wellness
A8: 6 | B8: Male | C8: A | D8: 2024JULB00006 | E8: Abhyuday Tripathi | F8: ='HPS grading'!K9 -> 58.275714 | G8: ='HPS grading'!P9 -> 49.946667 | H8: ='HPS grading'!U9 -> 66.865741 | I8: ='HPS grading'!Z9 -> 60.344947 | J8: =AVERAGE(F8,G8,H8,I8) -> 58.858267 | K8: {=_xlfn.IFS(J8>=80,"A+",J8>=70,"A",J8=60,"B+",J8>=50,"B",J8>=40,"C+",J8>=30,"C",J8>=20,"D",J8<20,"E")} -> B | L8: =' PEP Grade'!L9 -> With Held | M8: =' PEP Grade'!M9 -> Level 2 - Wellness
A9: 7 | B9: Male | C9: A | D9: 2024JULB00007 | E9: Adarsh G | F9: ='HPS grading'!K10 -> 67.376071 | G9: ='HPS grading'!P10 -> 43.433333 | H9: ='HPS grading'!U10 -> 50.237963 | I9: ='HPS grading'!Z10 -> 55.147259 | J9: =AVERAGE(F9,G9,H9,I9) -> 54.048657 | K9: {=_xlfn.IFS(J9>=80,"A+",J9>=70,"A",J9=60,"B+",J9>=50,"B",J9>=40,"C+",J9>=30,"C",J9>=20,"D",J9<20,"E")} -> B | L9: =' PEP Grade'!L10 -> With Held | M9: =' PEP Grade'!M10 -> Level 1 - Wellness, Level 2 - Wellness, Level 3 - Wellness
A10: 8 | B10: Male | C10: C | D10: 2024JULB00008 | E10: Adarsh Raj Barman | F10: ='HPS grading'!K11 -> 60.902381 | G10: ='HPS grading'!P11 -> 48.815556 | H10: ='HPS grading'!U11 -> 59.963889 | I10: ='HPS grading'!Z11 -> 56.750689 | J10: =AVERAGE(F10,G10,H10,I10) -> 56.608129 | K10: {=_xlfn.IFS(J10>=80,"A+",J10>=70,"A",J10=60,"B+",J10>=50,"B",J10>=40,"C+",J10>=30,"C",J10>=20,"D",J10<20,"E")} -> B | L10: =' PEP Grade'!L11 -> Passed | M10: =' PEP Grade'!M11
A11: 9 | B11: Female | C11: A | D11: 2024JULB00009 | E11: Aditi Kumari | F11: ='HPS grading'!K12 -> 61.93881 | G11: ='HPS grading'!P12 -> 55.163333 | H11: ='HPS grading'!U12 -> 62.644444 | I11: ='HPS grading'!Z12 -> 58.83248 | J11: =AVERAGE(F11,G11,H11,I11) -> 59.644767 | K11: {=_xlfn.IFS(J11>=80,"A+",J11>=70,"A",J11=60,"B+",J11>=50,"B",J11>=40,"C+",J11>=30,"C",J11>=20,"D",J11<20,"E")} -> B | L11: =' PEP Grade'!L12 -> Passed | M11: =' PEP Grade'!M12
A12: 10 | B12: Male | C12: A | D12: 2024JULB00012 | E12: Akarsh Narain | F12: ='HPS grading'!K13 -> 54.611429 | G12: ='HPS grading'!P13 -> 46.638889 | H12: ='HPS grading'!U13 -> 60.651852 | I12: ='HPS grading'!Z13 -> 57.194292 | J12: =AVERAGE(F12,G12,H12,I12) -> 54.774115 | K12: {=_xlfn.IFS(J12>=80,"A+",J12>=70,"A",J12=60,"B+",J12>=50,"B",J12>=40,"C+",J12>=30,"C",J12>=20,"D",J12<20,"E")} -> B | L12: =' PEP Grade'!L13 -> With Held | M12: =' PEP Grade'!M13 -> Level 1 - Wellness, Level 3 - Wellness
A13: 11 | B13: Male | C13: B | D13: 2024JULB00013 | E13: Akshat Singh | F13: ='HPS grading'!K14 -> 57.246429 | G13: ='HPS grading'!P14 -> 48.927778 | H13: ='HPS grading'!U14 -> 49.768148 | I13: ='HPS grading'!Z14 -> 52.048089 | J13: =AVERAGE(F13,G13,H13,I13) -> 51.997611 | K13: {=_xlfn.IFS(J13>=80,"A+",J13>=70,"A",J13=60,"B+",J13>=50,"B",J13>=40,"C+",J13>=30,"C",J13>=20,"D",J13<20,"E")} -> B | L13: =' PEP Grade'!L14 -> Passed | M13: =' PEP Grade'!M14
A14: 12 | B14: Male | C14: B | D14: 2024JULB00014 | E14: Amal Shibu Balan | F14: ='HPS grading'!K15 -> 38.377143 | G14: ='HPS grading'!P15 -> 53.047778 | H14: ='HPS grading'!U15 -> 55.635185 | I14: ='HPS grading'!Z15 -> 51.480304 | J14: =AVERAGE(F14,G14,H14,I14) -> 49.635103 | K14: {=_xlfn.IFS(J14>=80,"A+",J14>=70,"A",J14=60,"B+",J14>=50,"B",J14>=40,"C+",J14>=30,"C",J14>=20,"D",J14<20,"E")} -> C+ | L14: =' PEP Grade'!L15 -> With Held | M14: =' PEP Grade'!M15 -> Level 1 - Wellness
... A230: 228 | B230: Male | C230: D | D230: 2024JULB00273 | E230: Harshit Gopawat | F230: ='HPS grading'!K231 -> 3.6 | G230: ='HPS grading'!P231 -> 19.28 | H230: ='HPS grading'!U231 -> 30.035185 | I230: ='HPS grading'!Z231 -> 15.353796 | J230: =AVERAGE(F230,G230,H230,I230) -> 17.067245 | K230: {=_xlfn.IFS(J230>=80,"A+",J230>=70,"A",J230=60,"B+",J230>=50,"B",J230>=40,"C+",J230>=30,"C",J230>=20,"D",J230<20,"E")} -> E | L230: =' PEP Grade'!L231 -> With Held | M230: =' PEP Grade'!M231 -> Level 0 - Persona & Wellness, Level 1 - Persona & Wellness, Level 2 - Persona & Wellness, Level 3 - Persona & Wellness

Sheet Sheet6
A1: Sr # | B1: Gender | C1: Section | D1: RN | E1: Student name | F1: Holistic Personality Score All Levels | J1: HPS Grade | M1: Over all Performance
F2: Level 0 | G2: Level 1 | H2: Level 2 | I2: Level 3 | J2: FINAL HPS | K2: Grade | L2: Result | M2: Performance | O2: Performance Rating | Q2: Performance grade
A3: 1 | B3: Female | C3: A | D3: 2024JULB00001 | E3: A Divya Sree | F3: ='Final Sheet '!K4 -> 49.347222 | G3: ='Final Sheet '!V4 -> 53.71 | H3: ='Final Sheet '!AG4 -> 54.477778 | I3: ='Final Sheet '!AR4 -> 53.575926 | J3: =AVERAGE(F3,G3,H3,I3) -> 52.777731 | K3: {=_xlfn.IFS(J3>=80,"A+",J3>=70,"A",J3=60,"B+",J3>=50,"B",J3>=40,"C+",J3>=30,"C",J3>=20,"D",J3<20,"E")} -> B | L3: =' PEP Grade'!L4 -> With Held | M3: =I3-F3 -> 4.2287037 | N3: =IF(I3>F3*(1.2),"Significant Progress",IF(I3>F3*(1.1),"Moderate Progress",IF(AND(I3<=F3*(1.1),I3>=F3*0.95),"Maintained",IF(I3>=F3*0.86,"Minor Regression","Significant Regression")))) -> Maintained | O3: =IF(F3="","",IF((I3-F3)/F3>=0.2,5,IF((I3-F3)/F3>=0.1,4,IF((I3-F3)/F3>=-0.05,3,IF((I3-F3)/F3>=-0.14,2,1))))) -> 3 | Q3: =CHOOSE(MATCH(K3,{"A+","A","B+","B","C+","C","D","E"},0) - (O3-3),"A+","A","B+","B","C+","C","D","E") -> B
A4: 2 | B4: Male | C4: A | D4: 2024JULB00002 | E4: Aaditya K | F4: ='Final Sheet '!K5 -> 57.194444 | G4: ='Final Sheet '!V5 -> 65.319048 | H4: ='Final Sheet '!AG5 -> 35.257778 | I4: ='Final Sheet '!AR5 -> 58.859259 | J4: =AVERAGE(F4,G4,H4,I4) -> 54.157632 | K4: {=_xlfn.IFS(J4>=80,"A+",J4>=70,"A",J4=60,"B+",J4>=50,"B",J4>=40,"C+",J4>=30,"C",J4>=20,"D",J4<20,"E")} -> B | L4: =' PEP Grade'!L5 -> With Held | M4: =I4-F4 -> 1.6648148 | N4: =IF(I4>F4*(1.2),"Significant Progress",IF(I4>F4*(1.1),"Moderate Progress",IF(AND(I4<=F4*(1.1),I4>=F4*0.95),"Maintained",IF(I4>=F4*0.86,"Minor Regression","Significant Regression")))) -> Maintained | O4: =IF(F4="","",IF((I4-F4)/F4>=0.2,5,IF((I4-F4)/F4>=0.1,4,IF((I4-F4)/F4>=-0.05,3,IF((I4-F4)/F4>=-0.14,2,1))))) -> 3 | Q4: =CHOOSE(MATCH(K4,{"A+","A","B+","B","C+","C","D","E"},0) - (O4-3),"A+","A","B+","B","C+","C","D","E") -> B
A5: 3 | B5: Female | C5: A | D5: 2024JULB00003 | E5: Aanchal Sapra | F5: ='Final Sheet '!K6 -> 54.208333 | G5: ='Final Sheet '!V6 -> 44.435833 | H5: ='Final Sheet '!AG6 -> 33.617778 | I5: ='Final Sheet '!AR6 -> 38.742593 | J5: =AVERAGE(F5,G5,H5,I5) -> 42.751134 | K5: {=_xlfn.IFS(J5>=80,"A+",J5>=70,"A",J5=60,"B+",J5>=50,"B",J5>=40,"C+",J5>=30,"C",J5>=20,"D",J5<20,"E")} -> C+ | L5: =' PEP Grade'!L6 -> With Held | M5: =I5-F5 -> -15.465741 | N5: =IF(I5>F5*(1.2),"Significant Progress",IF(I5>F5*(1.1),"Moderate Progress",IF(AND(I5<=F5*(1.1),I5>=F5*0.95),"Maintained",IF(I5>=F5*0.86,"Minor Regression","Significant Regression")))) -> Significant Regression | O5: =IF(F5="","",IF((I5-F5)/F5>=0.2,5,IF((I5-F5)/F5>=0.1,4,IF((I5-F5)/F5>=-0.05,3,IF((I5-F5)/F5>=-0.14,2,1))))) -> 1 | Q5: =CHOOSE(MATCH(K5,{"A+","A","B+","B","C+","C","D","E"},0) - (O5-3),"A+","A","B+","B","C+","C","D","E") -> D
A6: 4 | B6: Male | C6: A | D6: 2024JULB00004 | E6: Abhinav B | F6: ='Final Sheet '!K7 -> 64.083333 | G6: ='Final Sheet '!V7 -> 46.654524 | H6: ='Final Sheet '!AG7 -> 45.537778 | I6: ='Final Sheet '!AR7 -> 55.72963 | J6: =AVERAGE(F6,G6,H6,I6) -> 53.001316 | K6: {=_xlfn.IFS(J6>=80,"A+",J6>=70,"A",J6=60,"B+",J6>=50,"B",J6>=40,"C+",J6>=30,"C",J6>=20,"D",J6<20,"E")} -> B | L6: =' PEP Grade'!L7 -> With Held | M6: =I6-F6 -> -8.3537037 | N6: =IF(I6>F6*(1.2),"Significant Progress",IF(I6>F6*(1.1),"Moderate Progress",IF(AND(I6<=F6*(1.1),I6>=F6*0.95),"Maintained",IF(I6>=F6*0.86,"Minor Regression","Significant Regression")))) -> Minor Regression | O6: =IF(F6="","",IF((I6-F6)/F6>=0.2,5,IF((I6-F6)/F6>=0.1,4,IF((I6-F6)/F6>=-0.05,3,IF((I6-F6)/F6>=-0.14,2,1))))) -> 2 | Q6: =CHOOSE(MATCH(K6,{"A+","A","B+","B","C+","C","D","E"},0) - (O6-3),"A+","A","B+","B","C+","C","D","E") -> C+
A7: 5 | B7: Male | C7: D | D7: 2024JULB00005 | E7: Abhirup Choudhury | F7: ='Final Sheet '!K8 -> 7.5 | G7: ='Final Sheet '!V8 -> 3.2 | H7: ='Final Sheet '!AG8 -> 30.004444 | I7: ='Final Sheet '!AR8 -> 6.0444444 | J7: =AVERAGE(F7,G7,H7,I7) -> 11.687222 | K7: {=_xlfn.IFS(J7>=80,"A+",J7>=70,"A",J7=60,"B+",J7>=50,"B",J7>=40,"C+",J7>=30,"C",J7>=20,"D",J7<20,"E")} -> E | L7: =' PEP Grade'!L8 -> With Held | M7: =I7-F7 -> -1.4555556 | N7: =IF(I7>F7*(1.2),"Significant Progress",IF(I7>F7*(1.1),"Moderate Progress",IF(AND(I7<=F7*(1.1),I7>=F7*0.95),"Maintained",IF(I7>=F7*0.86,"Minor Regression","Significant Regression")))) -> Significant Regression | O7: =IF(F7="","",IF((I7-F7)/F7>=0.2,5,IF((I7-F7)/F7>=0.1,4,IF((I7-F7)/F7>=-0.05,3,IF((I7-F7)/F7>=-0.14,2,1))))) -> 1 | Q7: =CHOOSE(MATCH(K7,{"A+","A","B+","B","C+","C","D","E"},0) - (O7-3),"A+","A","B+","B","C+","C","D","E") -> #VALUE!
A8: 6 | B8: Male | C8: A | D8: 2024JULB00006 | E8: Abhyuday Tripathi | F8: ='Final Sheet '!K9 -> 66.291667 | G8: ='Final Sheet '!V9 -> 58.275714 | H8: ='Final Sheet '!AG9 -> 48.646667 | I8: ='Final Sheet '!AR9 -> 66.865741 | J8: =AVERAGE(F8,G8,H8,I8) -> 60.019947 | K8: {=_xlfn.IFS(J8>=80,"A+",J8>=70,"A",J8=60,"B+",J8>=50,"B",J8>=40,"C+",J8>=30,"C",J8>=20,"D",J8<20,"E")} -> B | L8: =' PEP Grade'!L9 -> With Held | M8: =I8-F8 -> 0.57407407 | N8: =IF(I8>F8*(1.2),"Significant Progress",IF(I8>F8*(1.1),"Moderate Progress",IF(AND(I8<=F8*(1.1),I8>=F8*0.95),"Maintained",IF(I8>=F8*0.86,"Minor Regression","Significant Regression")))) -> Maintained | O8: =IF(F8="","",IF((I8-F8)/F8>=0.2,5,IF((I8-F8)/F8>=0.1,4,IF((I8-F8)/F8>=-0.05,3,IF((I8-F8)/F8>=-0.14,2,1))))) -> 3 | Q8: =CHOOSE(MATCH(K8,{"A+","A","B+","B","C+","C","D","E"},0) - (O8-3),"A+","A","B+","B","C+","C","D","E") -> B
A9: 7 | B9: Male | C9: A | D9: 2024JULB00007 | E9: Adarsh G | F9: ='Final Sheet '!K10 -> 59.541667 | G9: ='Final Sheet '!V10 -> 67.376071 | H9: ='Final Sheet '!AG10 -> 44.433333 | I9: ='Final Sheet '!AR10 -> 50.237963 | J9: =AVERAGE(F9,G9,H9,I9) -> 55.397259 | K9: {=_xlfn.IFS(J9>=80,"A+",J9>=70,"A",J9=60,"B+",J9>=50,"B",J9>=40,"C+",J9>=30,"C",J9>=20,"D",J9<20,"E")} -> B | L9: =' PEP Grade'!L10 -> With Held | M9: =I9-F9 -> -9.3037037 | N9: =IF(I9>F9*(1.2),"Significant Progress",IF(I9>F9*(1.1),"Moderate Progress",IF(AND(I9<=F9*(1.1),I9>=F9*0.95),"Maintained",IF(I9>=F9*0.86,"Minor Regression","Significant Regression")))) -> Significant Regression | O9: =IF(F9="","",IF((I9-F9)/F9>=0.2,5,IF((I9-F9)/F9>=0.1,4,IF((I9-F9)/F9>=-0.05,3,IF((I9-F9)/F9>=-0.14,2,1))))) -> 1 | Q9: =CHOOSE(MATCH(K9,{"A+","A","B+","B","C+","C","D","E"},0) - (O9-3),"A+","A","B+","B","C+","C","D","E") -> C
A10: 8 | B10: Male | C10: C | D10: 2024JULB00008 | E10: Adarsh Raj Barman | F10: ='Final Sheet '!K11 -> 57.320933 | G10: ='Final Sheet '!V11 -> 60.902381 | H10: ='Final Sheet '!AG11 -> 48.315556 | I10: ='Final Sheet '!AR11 -> 59.963889 | J10: =AVERAGE(F10,G10,H10,I10) -> 56.625689 | K10: {=_xlfn.IFS(J10>=80,"A+",J10>=70,"A",J10=60,"B+",J10>=50,"B",J10>=40,"C+",J10>=30,"C",J10>=20,"D",J10<20,"E")} -> B | L10: =' PEP Grade'!L11 -> Passed | M10: =I10-F10 -> 2.6429563 | N10: =IF(I10>F10*(1.2),"Significant Progress",IF(I10>F10*(1.1),"Moderate Progress",IF(AND(I10<=F10*(1.1),I10>=F10*0.95),"Maintained",IF(I10>=F10*0.86,"Minor Regression","Significant Regression")))) -> Maintained | O10: =IF(F10="","",IF((I10-F10)/F10>=0.2,5,IF((I10-F10)/F10>=0.1,4,IF((I10-F10)/F10>=-0.05,3,IF((I10-F10)/F10>=-0.14,2,1))))) -> 3 | Q10: =CHOOSE(MATCH(K10,{"A+","A","B+","B","C+","C","D","E"},0) - (O10-3),"A+","A","B+","B","C+","C","D","E") -> B
A11: 9 | B11: Female | C11: A | D11: 2024JULB00009 | E11: Aditi Kumari | F11: ='Final Sheet '!K12 -> 55.583333 | G11: ='Final Sheet '!V12 -> 61.93881 | H11: ='Final Sheet '!AG12 -> 55.363333 | I11: ='Final Sheet '!AR12 -> 62.644444 | J11: =AVERAGE(F11,G11,H11,I11) -> 58.88248 | K11: {=_xlfn.IFS(J11>=80,"A+",J11>=70,"A",J11=60,"B+",J11>=50,"B",J11>=40,"C+",J11>=30,"C",J11>=20,"D",J11<20,"E")} -> B | L11: =' PEP Grade'!L12 -> Passed | M11: =I11-F11 -> 7.0611111 | N11: =IF(I11>F11*(1.2),"Significant Progress",IF(I11>F11*(1.1),"Moderate Progress",IF(AND(I11<=F11*(1.1),I11>=F11*0.95),"Maintained",IF(I11>=F11*0.86,"Minor Regression","Significant Regression")))) -> Moderate Progress | O11: =IF(F11="","",IF((I11-F11)/F11>=0.2,5,IF((I11-F11)/F11>=0.1,4,IF((I11-F11)/F11>=-0.05,3,IF((I11-F11)/F11>=-0.14,2,1))))) -> 4 | Q11: =CHOOSE(MATCH(K11,{"A+","A","B+","B","C+","C","D","E"},0) - (O11-3),"A+","A","B+","B","C+","C","D","E") -> B+
A12: 10 | B12: Male | C12: A | D12: 2024JULB00012 | E12: Akarsh Narain | F12: ='Final Sheet '!K13 -> 66.875 | G12: ='Final Sheet '!V13 -> 54.611429 | H12: ='Final Sheet '!AG13 -> 46.605556 | I12: ='Final Sheet '!AR13 -> 60.651852 | J12: =AVERAGE(F12,G12,H12,I12) -> 57.185959 | K12: {=_xlfn.IFS(J12>=80,"A+",J12>=70,"A",J12=60,"B+",J12>=50,"B",J12>=40,"C+",J12>=30,"C",J12>=20,"D",J12<20,"E")} -> B | L12: =' PEP Grade'!L13 -> With Held | M12: =I12-F12 -> -6.2231481 | N12: =IF(I12>F12*(1.2),"Significant Progress",IF(I12>F12*(1.1),"Moderate Progress",IF(AND(I12<=F12*(1.1),I12>=F12*0.95),"Maintained",IF(I12>=F12*0.86,"Minor Regression","Significant Regression")))) -> Minor Regression | O12: =IF(F12="","",IF((I12-F12)/F12>=0.2,5,IF((I12-F12)/F12>=0.1,4,IF((I12-F12)/F12>=-0.05,3,IF((I12-F12)/F12>=-0.14,2,1))))) -> 2 | Q12: =CHOOSE(MATCH(K12,{"A+","A","B+","B","C+","C","D","E"},0) - (O12-3),"A+","A","B+","B","C+","C","D","E") -> C+
A13: 11 | B13: Male | C13: B | D13: 2024JULB00013 | E13: Akshat Singh | F13: ='Final Sheet '!K14 -> 52.25 | G13: ='Final Sheet '!V14 -> 57.246429 | H13: ='Final Sheet '!AG14 -> 48.557778 | I13: ='Final Sheet '!AR14 -> 49.768148 | J13: =AVERAGE(F13,G13,H13,I13) -> 51.955589 | K13: {=_xlfn.IFS(J13>=80,"A+",J13>=70,"A",J13=60,"B+",J13>=50,"B",J13>=40,"C+",J13>=30,"C",J13>=20,"D",J13<20,"E")} -> B | L13: =' PEP Grade'!L14 -> Passed | M13: =I13-F13 -> -2.4818519 | N13: =IF(I13>F13*(1.2),"Significant Progress",IF(I13>F13*(1.1),"Moderate Progress",IF(AND(I13<=F13*(1.1),I13>=F13*0.95),"Maintained",IF(I13>=F13*0.86,"Minor Regression","Significant Regression")))) -> Maintained | O13: =IF(F13="","",IF((I13-F13)/F13>=0.2,5,IF((I13-F13)/F13>=0.1,4,IF((I13-F13)/F13>=-0.05,3,IF((I13-F13)/F13>=-0.14,2,1))))) -> 3 | Q13: =CHOOSE(MATCH(K13,{"A+","A","B+","B","C+","C","D","E"},0) - (O13-3),"A+","A","B+","B","C+","C","D","E") -> B
A14: 12 | B14: Male | C14: B | D14: 2024JULB00014 | E14: Amal Shibu Balan | F14: ='Final Sheet '!K15 -> 58.861111 | G14: ='Final Sheet '!V15 -> 38.377143 | H14: ='Final Sheet '!AG15 -> 53.447778 | I14: ='Final Sheet '!AR15 -> 55.635185 | J14: =AVERAGE(F14,G14,H14,I14) -> 51.580304 | K14: {=_xlfn.IFS(J14>=80,"A+",J14>=70,"A",J14=60,"B+",J14>=50,"B",J14>=40,"C+",J14>=30,"C",J14>=20,"D",J14<20,"E")} -> B | L14: =' PEP Grade'!L15 -> With Held | M14: =I14-F14 -> -3.2259259 | N14: =IF(I14>F14*(1.2),"Significant Progress",IF(I14>F14*(1.1),"Moderate Progress",IF(AND(I14<=F14*(1.1),I14>=F14*0.95),"Maintained",IF(I14>=F14*0.86,"Minor Regression","Significant Regression")))) -> Minor Regression | O14: =IF(F14="","",IF((I14-F14)/F14>=0.2,5,IF((I14-F14)/F14>=0.1,4,IF((I14-F14)/F14>=-0.05,3,IF((I14-F14)/F14>=-0.14,2,1))))) -> 2 | Q14: =CHOOSE(MATCH(K14,{"A+","A","B+","B","C+","C","D","E"},0) - (O14-3),"A+","A","B+","B","C+","C","D","E") -> C+
... A230: 228 | B230: Male | C230: D | D230: 2024JULB00273 | E230: Harshit Gopawat | F230: ='Final Sheet '!K231 -> 8.5 | G230: ='Final Sheet '!V231 -> 3.6 | H230: ='Final Sheet '!AG231 -> 14.88 | I230: ='Final Sheet '!AR231 -> 30.035185 | J230: =AVERAGE(F230,G230,H230,I230) -> 14.253796 | K230: {=_xlfn.IFS(J230>=80,"A+",J230>=70,"A",J230=60,"B+",J230>=50,"B",J230>=40,"C+",J230>=30,"C",J230>=20,"D",J230<20,"E")} -> E | L230: =' PEP Grade'!L231 -> With Held | M230: =I230-F230 -> 21.535185 | N230: =IF(I230>F230*(1.2),"Significant Progress",IF(I230>F230*(1.1),"Moderate Progress",IF(AND(I230<=F230*(1.1),I230>=F230*0.95),"Maintained",IF(I230>=F230*0.86,"Minor Regression","Significant Regression")))) -> Significant Progress | O230: =IF(F230="","",IF((I230-F230)/F230>=0.2,5,IF((I230-F230)/F230>=0.1,4,IF((I230-F230)/F230>=-0.05,3,IF((I230-F230)/F230>=-0.14,2,1))))) -> 5 | Q230: =CHOOSE(MATCH(K230,{"A+","A","B+","B","C+","C","D","E"},0) - (O230-3),"A+","A","B+","B","C+","C","D","E") -> C

Sheet Final Sheet 
A1: RN | B1: Student name | C1: Level 0 / Term 1 | N1: Level 1 / Term 2 | Y1: Level 2 / Term 3 | AJ1: Level 3 / Term 4
C2: Persona | E2: Wellness | G2: Behavior | I2: Discipline | K2: Final HPS | L2: Result | N2: Persona | P2: Wellness | R2: Behavior | T2: Discipline | V2: Final HPS | W2: Result | Y2: Persona | AA2: Wellness | AC2: Behavior | AE2: Discipline | AG2: Final HPS | AH2: Result | AJ2: Persona | AL2: Wellness | AN2: Behavior | AP2: Discipline | AR2: Final HPS | AS2: Result
C3: Score | D3: Status | E3: Score | F3: Status | G3: Score | H3: Status | I3: Score | J3: Status | N3: Score | O3: Status | P3: Score | Q3: Status | R3: Score | S3: Status | T3: Score | U3: Status | Y3: Score | Z3: Status | AA3: Score | AB3: Status | AC3: Score | AD3: Status | AE3: Score | AF3: Status | AJ3: Score | AK3: Status | AL3: Score | AM3: Status | AN3: Score | AO3: Status | AP3: Score | AQ3: Status
A4: 2024JULB00001 | B4: A Divya Sree | C4: =Persona!Q99 -> 24.722222 | D4: =Persona!R5 -> Cleared | E4: =Wellness!T5 -> 13 | F4: =Wellness!W5 -> Cleared | G4: =Behavior!J5 -> 6 | H4: =Behavior!K5 -> Cleared | I4: =Discipline!O5 -> 5.625 | J4: =IF(I4>=6,"Cleared","NC") -> NC | K4: =C4+E4+G4+I4 -> 49.347222 | L4: =IF(D4&F4="ClearedCleared","Cleared",IF(D4="NC","Persona ","") &IF(F4="Attendance Test ","Wellness ","") &IF(F4="Attendance ","Wellness ","") &IF(F4="Test ","Wellness ","")) -> Cleared | N4: =Persona!AD5 -> 39.807143 | O4: =Persona!AE5 -> Cleared | P4: =Wellness!AN5 -> 0 | Q4: =Wellness!AQ5 -> Attendance Test | R4: =Behavior!R5 -> 8.6 | S4: =Behavior!S5 -> Cleared | T4: =Discipline!AB5 -> 5.3028571 | U4: =IF(T4>=6,"Cleared","NC") -> NC | V4: =N4+P4+R4+T4 -> 53.71 | W4: =IF(O4&Q4="ClearedCleared","Cleared",IF(O4="NC","Persona ","") &IF(Q4="Attendance Test ","Wellness ","") &IF(Q4="Attendance ","Wellness ","") &IF(Q4="Test ","Wellness ","")) -> Wellness | Y4: =Persona!AQ5 -> 34 | Z4: =Persona!AR5 -> Cleared | AA4: =Wellness!BH5 -> 10 | AB4: =Wellness!BK5 -> Cleared | AC4: =Behavior!Z5 -> 6.75 | AD4: =Behavior!AA5 -> Cleared | AE4: =Discipline!AO5 -> 3.7277778 | AF4: =IF(AE4>=6,"Cleared","NC") -> NC | AG4: =Y4+AA4+AC4+AE4 -> 54.477778 | AH4: =IF(Z4&AB4="ClearedCleared","Cleared",IF(Z4="NC","Persona ","") &IF(AB4="Attendance Test ","Wellness ","") &IF(AB4="Attendance ","Wellness ","") &IF(AB4="Test ","Wellness ","")) -> Cleared | AJ4: =Persona!BD5 -> 38.042593 | AK4: =Persona!BE5 -> Cleared | AL4: =Wellness!CB5 -> 3 | AM4: =Wellness!CE5 -> Test | AN4: =Behavior!AH5 -> 7.8 | AO4: =Behavior!AI5 -> Cleared | AP4: =Discipline!BB5 -> 4.7333333 | AQ4: =IF(AP4>=6,"Cleared","NC") -> NC | AR4: =AJ4+AL4+AN4+AP4 -> 53.575926 | AS4: =IF(AK4&AM4="ClearedCleared","Cleared",IF(AK4="NC","Persona ","") &IF(AM4="Attendance Test ","Wellness ","") &IF(AM4="Attendance ","Wellness ","") &IF(AM4="Test ","Wellness ","")) -> Wellness
A5: 2024JULB00002 | B5: Aaditya K | C5: =Persona!Q6 -> 24.444444 | D5: =Persona!R6 -> NC | E5: =Wellness!T6 -> 19 | F5: =Wellness!W6 -> Cleared | G5: =Behavior!J6 -> 6 | H5: =Behavior!K6 -> Cleared | I5: =Discipline!O6 -> 7.75 | J5: =IF(I5>=6,"Cleared","NC") -> Cleared | K5: =C5+E5+G5+I5 -> 57.194444 | L5: =IF(D5&F5="ClearedCleared","Cleared",IF(D5="NC","Persona ","") &IF(F5="Attendance Test ","Wellness ","") &IF(F5="Attendance ","Wellness ","") &IF(F5="Test ","Wellness ","")) -> Persona | N5: =Persona!AD6 -> 35.761905 | O5: =Persona!AE6 -> Cleared | P5: =Wellness!AN6 -> 16 | Q5: =Wellness!AQ6 -> Cleared | R5: =Behavior!R6 -> 7.1 | S5: =Behavior!S6 -> Cleared | T5: =Discipline!AB6 -> 6.4571429 | U5: =IF(T5>=6,"Cleared","NC") -> Cleared | V5: =N5+P5+R5+T5 -> 65.319048 | W5: =IF(O5&Q5="ClearedCleared","Cleared",IF(O5="NC","Persona ","") &IF(Q5="Attendance Test ","Wellness ","") &IF(Q5="Attendance ","Wellness ","") &IF(Q5="Test ","Wellness ","")) -> Cleared | Y5: =Persona!AQ6 -> 22.046667 | Z5: =Persona!AR6 -> NC | AA5: =Wellness!BH6 -> 5 | AB5: =Wellness!BK6 -> Test | AC5: =Behavior!Z6 -> 4.5 | AD5: =Behavior!AA6 -> NC | AE5: =Discipline!AO6 -> 3.7111111 | AF5: =IF(AE5>=6,"Cleared","NC") -> NC | AG5: =Y5+AA5+AC5+AE5 -> 35.257778 | AH5: =IF(Z5&AB5="ClearedCleared","Cleared",IF(Z5="NC","Persona ","") &IF(AB5="Attendance Test ","Wellness ","") &IF(AB5="Attendance ","Wellness ","") &IF(AB5="Test ","Wellness ","")) -> Persona Wellness | AJ5: =Persona!BD6 -> 31.459259 | AK5: =Persona!BE6 -> Cleared | AL5: =Wellness!CB6 -> 16 | AM5: =Wellness!CE6 -> Cleared | AN5: =Behavior!AH6 -> 5.6 | AO5: =Behavior!AI6 -> NC | AP5: =Discipline!BB6 -> 5.8 | AQ5: =IF(AP5>=6,"Cleared","NC") -> NC | AR5: =AJ5+AL5+AN5+AP5 -> 58.859259 | AS5: =IF(AK5&AM5="ClearedCleared","Cleared",IF(AK5="NC","Persona ","") &IF(AM5="Attendance Test ","Wellness ","") &IF(AM5="Attendance ","Wellness ","") &IF(AM5="Test ","Wellness ","")) -> Cleared
A6: 2024JULB00003 | B6: Aanchal Sapra | C6: =Persona!Q7 -> 33.333333 | D6: =Persona!R7 -> Cleared | E6: =Wellness!T7 -> 11 | F6: =Wellness!W7 -> Cleared | G6: =Behavior!J7 -> 6 | H6: =Behavior!K7 -> Cleared | I6: =Discipline!O7 -> 3.875 | J6: =IF(I6>=6,"Cleared","NC") -> NC | K6: =C6+E6+G6+I6 -> 54.208333 | L6: =IF(D6&F6="ClearedCleared","Cleared",IF(D6="NC","Persona ","") &IF(F6="Attendance Test ","Wellness ","") &IF(F6="Attendance ","Wellness ","") &IF(F6="Test ","Wellness ","")) -> Cleared | N6: =Persona!AD7 -> 31.710119 | O6: =Persona!AE7 -> Cleared | P6: =Wellness!AN7 -> 4 | Q6: =Wellness!AQ7 -> Attendance Test | R6: =Behavior!R7 -> 5.4 | S6: =Behavior!S7 -> NC | T6: =Discipline!AB7 -> 3.3257143 | U6: =IF(T6>=6,"Cleared","NC") -> NC | V6: =N6+P6+R6+T6 -> 44.435833 | W6: =IF(O6&Q6="ClearedCleared","Cleared",IF(O6="NC","Persona ","") &IF(Q6="Attendance Test ","Wellness ","") &IF(Q6="Attendance ","Wellness ","") &IF(Q6="Test ","Wellness ","")) -> Wellness | Y6: =Persona!AQ7 -> 24.406667 | Z6: =Persona!AR7 -> NC | AA6: =Wellness!BH7 -> 5 | AB6: =Wellness!BK7 -> Attendance Test | AC6: =Behavior!Z7 -> 2.5 | AD6: =Behavior!AA7 -> NC | AE6: =Discipline!AO7 -> 1.7111111 | AF6: =IF(AE6>=6,"Cleared","NC") -> NC | AG6: =Y6+AA6+AC6+AE6 -> 33.617778 | AH6: =IF(Z6&AB6="ClearedCleared","Cleared",IF(Z6="NC","Persona ","") &IF(AB6="Attendance Test ","Wellness ","") &IF(AB6="Attendance ","Wellness ","") &IF(AB6="Test ","Wellness ","")) -> Persona Wellness | AJ6: =Persona!BD7 -> 27.375926 | AK6: =Persona!BE7 -> Cleared | AL6: =Wellness!CB7 -> 3 | AM6: =Wellness!CE7 -> Attendance Test | AN6: =Behavior!AH7 -> 4 | AO6: =Behavior!AI7 -> NC | AP6: =Discipline!BB7 -> 4.3666667 | AQ6: =IF(AP6>=6,"Cleared","NC") -> NC | AR6: =AJ6+AL6+AN6+AP6 -> 38.742593 | AS6: =IF(AK6&AM6="ClearedCleared","Cleared",IF(AK6="NC","Persona ","") &IF(AM6="Attendance Test ","Wellness ","") &IF(AM6="Attendance ","Wellness ","") &IF(AM6="Test ","Wellness ","")) -> Wellness | AV6: Status | AW6: Level 0 | AX6: Level 1 | AY6: Level 2 | AZ6: Level 3
A7: 2024JULB00004 | B7: Abhinav B | C7: =Persona!Q8 -> 33.333333 | D7: =Persona!R8 -> Cleared | E7: =Wellness!T8 -> 19 | F7: =Wellness!W8 -> Cleared | G7: =Behavior!J8 -> 6 | H7: =Behavior!K8 -> Cleared | I7: =Discipline!O8 -> 5.75 | J7: =IF(I7>=6,"Cleared","NC") -> NC | K7: =C7+E7+G7+I7 -> 64.083333 | L7: =IF(D7&F7="ClearedCleared","Cleared",IF(D7="NC","Persona ","") &IF(F7="Attendance Test ","Wellness ","") &IF(F7="Attendance ","Wellness ","") &IF(F7="Test ","Wellness ","")) -> Cleared | N7: =Persona!AD8 -> 32.691667 | O7: =Persona!AE8 -> Cleared | P7: =Wellness!AN8 -> 5 | Q7: =Wellness!AQ8 -> Test | R7: =Behavior!R8 -> 5.1 | S7: =Behavior!S8 -> NC | T7: =Discipline!AB8 -> 3.8628571 | U7: =IF(T7>=6,"Cleared","NC") -> NC | V7: =N7+P7+R7+T7 -> 46.654524 | W7: =IF(O7&Q7="ClearedCleared","Cleared",IF(O7="NC","Persona ","") &IF(Q7="Attendance Test ","Wellness ","") &IF(Q7="Attendance ","Wellness ","") &IF(Q7="Test ","Wellness ","")) -> Wellness | Y7: =Persona!AQ8 -> 18.126667 | Z7: =Persona!AR8 -> NC | AA7: =Wellness!BH8 -> 19 | AB7: =Wellness!BK8 -> Attendance | AC7: =Behavior!Z8 -> 5.5 | AD7: =Behavior!AA8 -> NC | AE7: =Discipline!AO8 -> 2.9111111 | AF7: =IF(AE7>=6,"Cleared","NC") -> NC | AG7: =Y7+AA7+AC7+AE7 -> 45.537778 | AH7: =IF(Z7&AB7="ClearedCleared","Cleared",IF(Z7="NC","Persona ","") &IF(AB7="Attendance Test ","Wellness ","") &IF(AB7="Attendance ","Wellness ","") &IF(AB7="Test ","Wellness ","")) -> Persona Wellness | AJ7: =Persona!BD8 -> 29.262963 | AK7: =Persona!BE8 -> Cleared | AL7: =Wellness!CB8 -> 15 | AM7: =Wellness!CE8 -> Attendance | AN7: =Behavior!AH8 -> 6.4 | AO7: =Behavior!AI8 -> Cleared | AP7: =Discipline!BB8 -> 5.0666667 | AQ7: =IF(AP7>=6,"Cleared","NC") -> NC | AR7: =AJ7+AL7+AN7+AP7 -> 55.72963 | AS7: =IF(AK7&AM7="ClearedCleared","Cleared",IF(AK7="NC","Persona ","") &IF(AM7="Attendance Test ","Wellness ","") &IF(AM7="Attendance ","Wellness ","") &IF(AM7="Test ","Wellness ","")) -> Wellness | AV7: Cleared | AW7: =COUNTIF($L$4:$L$231,"Cleared") -> 133 | AX7: =COUNTIF($W$4:$W$231,"Cleared") -> 51 | AY7: =COUNTIF($AH$4:$AH$231,"Cleared") -> 77 | AZ7: =COUNTIF($AS$4:$AS$231,"Cleared") -> 89
A8: 2024JULB00005 | B8: Abhirup Choudhury | C8: =Persona!Q9 -> 0 | D8: =Persona!R9 -> NC | E8: =Wellness!T9 -> 0 | F8: =Wellness!W9 -> Attendance Test | G8: =Behavior!J9 -> 6 | H8: =Behavior!K9 -> Cleared | I8: =Discipline!O9 -> 1.5 | J8: =IF(I8>=6,"Cleared","NC") -> NC | K8: =C8+E8+G8+I8 -> 7.5 | L8: =IF(D8&F8="ClearedCleared","Cleared",IF(D8="NC","Persona ","") &IF(F8="Attendance Test ","Wellness ","") &IF(F8="Attendance ","Wellness ","") &IF(F8="Test ","Wellness ","")) -> Persona Wellness | N8: =Persona!AD9 -> 0 | O8: =Persona!AE9 -> NC | P8: =Wellness!AN9 -> 0 | Q8: =Wellness!AQ9 -> Attendance Test | R8: =Behavior!R9 -> 3.2 | S8: =Behavior!S9 -> NC | T8: =Discipline!AB9 -> 0 | U8: =IF(T8>=6,"Cleared","NC") -> NC | V8: =N8+P8+R8+T8 -> 3.2 | W8: =IF(O8&Q8="ClearedCleared","Cleared",IF(O8="NC","Persona ","") &IF(Q8="Attendance Test ","Wellness ","") &IF(Q8="Attendance ","Wellness ","") &IF(Q8="Test ","Wellness ","")) -> Persona Wellness | Y8: =Persona!AQ9 -> 25.493333 | Z8: =Persona!AR9 -> Cleared | AA8: =Wellness!BH9 -> 0 | AB8: =Wellness!BK9 -> Attendance Test | AC8: =Behavior!Z9 -> 1 | AD8: =Behavior!AA9 -> NC | AE8: =Discipline!AO9 -> 3.5111111 | AF8: =IF(AE8>=6,"Cleared","NC") -> NC | AG8: =Y8+AA8+AC8+AE8 -> 30.004444 | AH8: =IF(Z8&AB8="ClearedCleared","Cleared",IF(Z8="NC","Persona ","") &IF(AB8="Attendance Test ","Wellness ","") &IF(AB8="Attendance ","Wellness ","") &IF(AB8="Test ","Wellness ","")) -> Wellness | AJ8: =Persona!BD9 -> 4.4444444 | AK8: =Persona!BE9 -> NC | AL8: =Wellness!CB9 -> 0 | AM8: =Wellness!CE9 -> Attendance Test | AN8: =Behavior!AH9 -> 0 | AO8: =Behavior!AI9 -> NC | AP8: =Discipline!BB9 -> 1.6 | AQ8: =IF(AP8>=6,"Cleared","NC") -> NC | AR8: =AJ8+AL8+AN8+AP8 -> 6.0444444 | AS8: =IF(AK8&AM8="ClearedCleared","Cleared",IF(AK8="NC","Persona ","") &IF(AM8="Attendance Test ","Wellness ","") &IF(AM8="Attendance ","Wellness ","") &IF(AM8="Test ","Wellness ","")) -> Persona Wellness | AV8: Persona Affliction | AW8: =COUNTIF($L$4:$L$231,"Persona ") -> 52 | AX8: =COUNTIF($W$4:$W$231,"Persona ") -> 21 | AY8: =COUNTIF($AH$4:$AH$231,"Persona ") -> 16 | AZ8: =COUNTIF($AS$4:$AS$231,"Persona ") -> 13
A9: 2024JULB00006 | B9: Abhyuday Tripathi | C9: =Persona!Q10 -> 36.666667 | D9: =Persona!R10 -> Cleared | E9: =Wellness!T10 -> 16 | F9: =Wellness!W10 -> Cleared | G9: =Behavior!J10 -> 6 | H9: =Behavior!K10 -> Cleared | I9: =Discipline!O10 -> 7.625 | J9: =IF(I9>=6,"Cleared","NC") -> Cleared | K9: =C9+E9+G9+I9 -> 66.291667 | L9: =IF(D9&F9="ClearedCleared","Cleared",IF(D9="NC","Persona ","") &IF(F9="Attendance Test ","Wellness ","") &IF(F9="Attendance ","Wellness ","") &IF(F9="Test ","Wellness ","")) -> Cleared | N9: =Persona!AD10 -> 36.835714 | O9: =Persona!AE10 -> Cleared | P9: =Wellness!AN10 -> 10 | Q9: =Wellness!AQ10 -> Cleared | R9: =Behavior!R10 -> 6.4 | S9: =Behavior!S10 -> Cleared | T9: =Discipline!AB10 -> 5.04 | U9: =IF(T9>=6,"Cleared","NC") -> NC | V9: =N9+P9+R9+T9 -> 58.275714 | W9: =IF(O9&Q9="ClearedCleared","Cleared",IF(O9="NC","Persona ","") &IF(Q9="Attendance Test ","Wellness ","") &IF(Q9="Attendance ","Wellness ","") &IF(Q9="Test ","Wellness ","")) -> Cleared | Y9: =Persona!AQ10 -> 32.413333 | Z9: =Persona!AR10 -> Cleared | AA9: =Wellness!BH10 -> 6 | AB9: =Wellness!BK10 -> Test | AC9: =Behavior!Z10 -> 6.3 | AD9: =Behavior!AA10 -> Cleared | AE9: =Discipline!AO10 -> 3.9333333 | AF9: =IF(AE9>=6,"Cleared","NC") -> NC | AG9: =Y9+AA9+AC9+AE9 -> 48.646667 | AH9: =IF(Z9&AB9="ClearedCleared","Cleared",IF(Z9="NC","Persona ","") &IF(AB9="Attendance Test ","Wellness ","") &IF(AB9="Attendance ","Wellness ","") &IF(AB9="Test ","Wellness ","")) -> Wellness | AJ9: =Persona!BD10 -> 36.332407 | AK9: =Persona!BE10 -> Cleared | AL9: =Wellness!CB10 -> 17 | AM9: =Wellness!CE10 -> Cleared | AN9: =Behavior!AH10 -> 7.6 | AO9: =Behavior!AI10 -> Cleared | AP9: =Discipline!BB10 -> 5.9333333 | AQ9: =IF(AP9>=6,"Cleared","NC") -> NC | AR9: =AJ9+AL9+AN9+AP9 -> 66.865741 | AS9: =IF(AK9&AM9="ClearedCleared","Cleared",IF(AK9="NC","Persona ","") &IF(AM9="Attendance Test ","Wellness ","") &IF(AM9="Attendance ","Wellness ","") &IF(AM9="Test ","Wellness ","")) -> Cleared | AV9: Wellness Affliction | AW9: =COUNTIF($L$4:$L$231,"Wellness ") -> 30 | AX9: =COUNTIF($W$4:$W$231,"Wellness ") -> 100 | AY9: =COUNTIF($AH$4:$AH$231,"Wellness ") -> 98 | AZ9: =COUNTIF($AS$4:$AS$231,"Wellness ") -> 105
A10: 2024JULB00007 | B10: Adarsh G | C10: =Persona!Q11 -> 31.666667 | D10: =Persona!R11 -> Cleared | E10: =Wellness!T11 -> 15 | F10: =Wellness!W11 -> Cleared | G10: =Behavior!J11 -> 6 | H10: =Behavior!K11 -> Cleared | I10: =Discipline!O11 -> 6.875 | J10: =IF(I10>=6,"Cleared","NC") -> Cleared | K10: =C10+E10+G10+I10 -> 59.541667 | L10: =IF(D10&F10="ClearedCleared","Cleared",IF(D10="NC","Persona ","") &IF(F10="Attendance Test ","Wellness ","") &IF(F10="Attendance ","Wellness ","") &IF(F10="Test ","Wellness ","")) -> Cleared | N10: =Persona!AD11 -> 40.430357 | O10: =Persona!AE11 -> Cleared | P10: =Wellness!AN11 -> 15 | Q10: =Wellness!AQ11 -> Attendance | R10: =Behavior!R11 -> 6.7 | S10: =Behavior!S11 -> Cleared | T10: =Discipline!AB11 -> 5.2457143 | U10: =IF(T10>=6,"Cleared","NC") -> NC | V10: =N10+P10+R10+T10 -> 67.376071 | W10: =IF(O10&Q10="ClearedCleared","Cleared",IF(O10="NC","Persona ","") &IF(Q10="Attendance Test ","Wellness ","") &IF(Q10="Attendance ","Wellness ","") &IF(Q10="Test ","Wellness ","")) -> Wellness | Y10: =Persona!AQ11 -> 28.4 | Z10: =Persona!AR11 -> Cleared | AA10: =Wellness!BH11 -> 7 | AB10: =Wellness!BK11 -> Attendance Test | AC10: =Behavior!Z11 -> 7 | AD10: =Behavior!AA11 -> Cleared | AE10: =Discipline!AO11 -> 2.0333333 | AF10: =IF(AE10>=6,"Cleared","NC") -> NC | AG10: =Y10+AA10+AC10+AE10 -> 44.433333 | AH10: =IF(Z10&AB10="ClearedCleared","Cleared",IF(Z10="NC","Persona ","") &IF(AB10="Attendance Test ","Wellness ","") &IF(AB10="Attendance ","Wellness ","") &IF(AB10="Test ","Wellness ","")) -> Wellness | AJ10: =Persona!BD11 -> 28.987963 | AK10: =Persona!BE11 -> Cleared | AL10: =Wellness!CB11 -> 10 | AM10: =Wellness!CE11 -> Attendance | AN10: =Behavior!AH11 -> 6 | AO10: =Behavior!AI11 -> Cleared | AP10: =Discipline!BB11 -> 5.25 | AQ10: =IF(AP10>=6,"Cleared","NC") -> NC | AR10: =AJ10+AL10+AN10+AP10 -> 50.237963 | AS10: =IF(AK10&AM10="ClearedCleared","Cleared",IF(AK10="NC","Persona ","") &IF(AM10="Attendance Test ","Wellness ","") &IF(AM10="Attendance ","Wellness ","") &IF(AM10="Test ","Wellness ","")) -> Wellness | AV10: Persona & Wellness Affliction | AW10: =COUNTIF($L$4:$L$231,"Persona Wellness ") -> 13 | AX10: =COUNTIF($W$4:$W$231,"Persona Wellness ") -> 56 | AY10: =COUNTIF($AH$4:$AH$231,"Persona Wellness ") -> 37 | AZ10: =COUNTIF($AS$4:$AS$231,"Persona Wellness ") -> 21
A11: 2024JULB00008 | B11: Adarsh Raj Barman | C11: =Persona!Q12 -> 31.111111 | D11: =Persona!R12 -> Cleared | E11: =Wellness!T12 -> 14 | F11: =Wellness!W12 -> Cleared | G11: =Behavior!J12 -> 6 | H11: =Behavior!K12 -> Cleared | I11: =Discipline!O12 -> 6.2098214 | J11: =IF(I11>=6,"Cleared","NC") -> Cleared | K11: =C11+E11+G11+I11 -> 57.320933 | L11: =IF(D11&F11="ClearedCleared","Cleared",IF(D11="NC","Persona ","") &IF(F11="Attendance Test ","Wellness ","") &IF(F11="Attendance ","Wellness ","") &IF(F11="Test ","Wellness ","")) -> Cleared | N11: =Persona!AD12 -> 35.616667 | O11: =Persona!AE12 -> Cleared | P11: =Wellness!AN12 -> 11 | Q11: =Wellness!AQ12 -> Cleared | R11: =Behavior!R12 -> 8.4 | S11: =Behavior!S12 -> Cleared | T11: =Discipline!AB12 -> 5.8857143 | U11: =IF(T11>=6,"Cleared","NC") -> NC | V11: =N11+P11+R11+T11 -> 60.902381 | W11: =IF(O11&Q11="ClearedCleared","Cleared",IF(O11="NC","Persona ","") &IF(Q11="Attendance Test ","Wellness ","") &IF(Q11="Attendance ","Wellness ","") &IF(Q11="Test ","Wellness ","")) -> Cleared | Y11: =Persona!AQ12 -> 27.16 | Z11: =Persona!AR12 -> Cleared | AA11: =Wellness!BH12 -> 10 | AB11: =Wellness!BK12 -> Cleared | AC11: =Behavior!Z12 -> 5.5 | AD11: =Behavior!AA12 -> NC | AE11: =Discipline!AO12 -> 5.6555556 | AF11: =IF(AE11>=6,"Cleared","NC") -> NC | AG11: =Y11+AA11+AC11+AE11 -> 48.315556 | AH11: =IF(Z11&AB11="ClearedCleared","Cleared",IF(Z11="NC","Persona ","") &IF(AB11="Attendance Test ","Wellness ","") &IF(AB11="Attendance ","Wellness ","") &IF(AB11="Test ","Wellness ","")) -> Cleared | AJ11: =Persona!BD12 -> 37.313889 | AK11: =Persona!BE12 -> Cleared | AL11: =Wellness!CB12 -> 11 | AM11: =Wellness!CE12 -> Cleared | AN11: =Behavior!AH12 -> 6 | AO11: =Behavior!AI12 -> Cleared | AP11: =Discipline!BB12 -> 5.65 | AQ11: =IF(AP11>=6,"Cleared","NC") -> NC | AR11: =AJ11+AL11+AN11+AP11 -> 59.963889 | AS11: =IF(AK11&AM11="ClearedCleared","Cleared",IF(AK11="NC","Persona ","") &IF(AM11="Attendance Test ","Wellness ","") &IF(AM11="Attendance ","Wellness ","") &IF(AM11="Test ","Wellness ","")) -> Cleared | AV11: Total | AW11: =SUM(AW7:AW10) -> 228 | AX11: =SUM(AX7:AX10) -> 228 | AY11: =SUM(AY7:AY10) -> 228 | AZ11: =SUM(AZ7:AZ10) -> 228
A12: 2024JULB00009 | B12: Aditi Kumari | C12: =Persona!Q13 -> 28.333333 | D12: =Persona!R13 -> Cleared | E12: =Wellness!T13 -> 14 | F12: =Wellness!W13 -> Cleared | G12: =Behavior!J13 -> 6 | H12: =Behavior!K13 -> Cleared | I12: =Discipline!O13 -> 7.25 | J12: =IF(I12>=6,"Cleared","NC") -> Cleared | K12: =C12+E12+G12+I12 -> 55.583333 | L12: =IF(D12&F12="ClearedCleared","Cleared",IF(D12="NC","Persona ","") &IF(F12="Attendance Test ","Wellness ","") &IF(F12="Attendance ","Wellness ","") &IF(F12="Test ","Wellness ","")) -> Cleared | N12: =Persona!AD13 -> 34.270238 | O12: =Persona!AE13 -> Cleared | P12: =Wellness!AN13 -> 15 | Q12: =Wellness!AQ13 -> Cleared | R12: =Behavior!R13 -> 6.2 | S12: =Behavior!S13 -> Cleared | T12: =Discipline!AB13 -> 6.4685714 | U12: =IF(T12>=6,"Cleared","NC") -> Cleared | V12: =N12+P12+R12+T12 -> 61.93881 | W12: =IF(O12&Q12="ClearedCleared","Cleared",IF(O12="NC","Persona ","") &IF(Q12="Attendance Test ","Wellness ","") &IF(Q12="Attendance ","Wellness ","") &IF(Q12="Test ","Wellness ","")) -> Cleared | Y12: =Persona!AQ13 -> 28.68 | Z12: =Persona!AR13 -> Cleared | AA12: =Wellness!BH13 -> 14 | AB12: =Wellness!BK13 -> Cleared | AC12: =Behavior!Z13 -> 7 | AD12: =Behavior!AA13 -> Cleared | AE12: =Discipline!AO13 -> 5.6833333 | AF12: =IF(AE12>=6,"Cleared","NC") -> NC | AG12: =Y12+AA12+AC12+AE12 -> 55.363333 | AH12: =IF(Z12&AB12="ClearedCleared","Cleared",IF(Z12="NC","Persona ","") &IF(AB12="Attendance Test ","Wellness ","") &IF(AB12="Attendance ","Wellness ","") &IF(AB12="Test ","Wellness ","")) -> Cleared | AJ12: =Persona!BD13 -> 34.661111 | AK12: =Persona!BE13 -> Cleared | AL12: =Wellness!CB13 -> 15 | AM12: =Wellness!CE13 -> Cleared | AN12: =Behavior!AH13 -> 6.8 | AO12: =Behavior!AI13 -> Cleared | AP12: =Discipline!BB13 -> 6.1833333 | AQ12: =IF(AP12>=6,"Cleared","NC") -> Cleared | AR12: =AJ12+AL12+AN12+AP12 -> 62.644444 | AS12: =IF(AK12&AM12="ClearedCleared","Cleared",IF(AK12="NC","Persona ","") &IF(AM12="Attendance Test ","Wellness ","") &IF(AM12="Attendance ","Wellness ","") &IF(AM12="Test ","Wellness ","")) -> Cleared
